Workbook

Sheet 1. ΟΔΗΓΟΣ ΑΡΧΕΙΩΝ & ΣΥΣΤΗΜΑΤΟΣ
A1: ΟΔΗΓΟΣ ΑΡΧΕΙΩΝ & ΣΥΣΤΗΜΑΤΟΣ ΠΑΡΑΓΩΓΗΣ / ΕΚΚΑΘΑΡΙΣΕΩΝ ERGO (ΔΑΣ)
A2: Αναλυτικός Οδηγός Επεξήγησης Αρχείων, Σημασίας Πεδίων, Ροής Δεδομένων και Συσχετίσεων Γραφείου 1411 (LANCA Ε.Ε.)
A4: Α. ΕΠΙΣΚΟΠΗΣΗ & ΤΑΥΤΟΤΗΤΑ ΑΡΧΕΙΩΝ ΕΤΑΙΡΙΑΣ ERGO / ΔΑΣ
A5: Τύπος Αρχείου / Μοτίβο Ονομασίας | B5: Ελληνική Ονομασία & Περιγραφή | C5: Κύριος Σκοπός & Περιεχόμενο | D5: Συχνότητα | E5: Τι Περιλαμβάνει Αναλυτικά | F5: Πώς Χρησιμοποιείται από το Γραφείο 1411 | G5: Σύνδεση με Άλλα Αρχεία (Relational Link)
A6: 1411-ΜΗΤΡΩΟ ΠΑΡΑΓΩΓΗΣ MM_2026.csv | B6: Μητρώο Νέας Παραγωγής & Κινήσεων Μηνός | C6: Επίσημη καταγραφή όλων των νέων συμβολαίων, προσθηκών και κινήσεων που εκδόθηκαν εντός του μηνός. | D6: Μηνιαία | E6: Αρ. Συμβολαίου, Αρ. Απόδειξης, Κωδικός Συνεργάτη, Ονοματεπώνυμο Πελάτη, Ημ/νία Έκδοσης, Ημ/νία Έναρξης, Διάρκεια, Μικτά, Καθαρά, Δικαιώματα, Προμήθειες. | F6: Έλεγχος και επιβεβαίωση της νέας παραγωγής του γραφείου και των συνεργατών. Καταμέτρηση νέων πελατών και υπολογισμός στόχων. | G6: Συνδέεται με UATOP612 & ΠΡΟΜΗΘΕΙΕΣ μέσω του Αριθμού Συμβολαίου.
A7: 1411-ΠΙΝΑΚΙΟ ΑΝΑΝΕΩΣΕΩΝ MM_2026.csv | B7: Πινάκιο Ανανεώσεων (Ενημερωτικό / Πρόβλεψη) | C7: Ενημερωτική κατάσταση επικείμενων ανανεώσεων για πληροφόρηση του συνεργάτη (τι αναμένεται να εισπραχθεί και να πιστωθεί). | D7: Μηνιαία | E7: Αρ. Συμβολαίου, Αρ. Απόδειξης, Ονοματεπώνυμο, Ημ/νία Ανανέωσης, Τρόπος Πληρωμής, Αναμενόμενα Μικτά/Καθαρά, Αναμενόμενη Προμήθεια Συνεργάτη. | F7: Χρησιμεύει ως εργαλείο πρόβλεψης & ενημέρωσης του συνεργάτη για το τι περιμένει να λάβει. ΔΕΝ αποτελεί τελική ταμειακή εκκαθάριση (η επίσημη πληρωμή προμηθειών & υπερπρομηθειών πραγματοποιείται ΜΟΝΟ από τα αρχεία 1411-ΠΡΟΜΗΘΕΙΕΣ μετά την είσπραξη). | G7: Συνδέεται με το αρχείο ΠΡΟΜΗΘΕΙΕΣ αφού πληρωθεί το ασφαλιστήριο συμβόλαιο.
A8: 1411-ΠΡΟΜΗΘΕΙΕΣ - ΥΠΕΡΠΡΟΜΗΘΕΙΕΣ MM_2026.csv | B8: Μηνιαία Εκκαθάριση Προμηθειών & Υπερπρομηθειών | C8: Το επίσημο εκκαθαριστικό σημείωμα (Statement) πληρωμών αμοιβών παραγωγών και υπερπρομηθειών δικτύου. | D8: Μηνιαία | E8: Διαχωρισμός εγγραφών ανά ρόλο (ΠΑΡΑΓΩΓΟΣ vs AGENCY), Αρ. Συμβολαίου, Αρ. Απόδειξης, Κλάδος (Ζωή, Υγεία), Καθαρά Ασφάλιστρα, Ποσό Προμήθειας, Ποσό Υπερπρομήθειας Agency (20%). | F8: Το κεντρικό αρχείο οικονομικής εκκαθάρισης. Από εδώ προκύπτει τι πιστώνεται στον συνεργάτη και τι κερδίζει το Γραφείο 1411 (LANCA Ε.Ε.) ως Υπερπρομήθεια Δικτύου. | G8: Αποτελεί το οικονομικό αποτέλεσμα της σύζευξης Μητρώου Παραγωγής και Πινακίου Ανανεώσεων.
A9: 1411-UATOP612_MONTH_DD_MM_2026.csv | B9: Κεντρικό Μητρώο Συμβολαίων, Αποδείξεων & Οικονομικών Μεγεθών (Core Ledger) | C9: Το θεμελιώδες master record του συστήματος της ERGO. Περιέχει την πλήρη ανάλυση μικτών, καθαρών, φόρων, δικαιωμάτων και όλων των βαθμίδων προμηθειών. | D9: Μηνιαία | E9: F612SYM (Συμβόλαιο), F612APD (Απόδειξη), F612MIK (Μικτά), F612ASK (Καθαρά), F612DIK (Δικαίωμα), F612FKE (Φόρος), F612PPO (Προμήθεια Παραγωγού), F612PAG (Υπερπρομήθεια Agency), F612PUN (Unit), F612KLEIDI. | F9: Αποτελεί την πηγή αλήθειας για κάθε οικονομικό υπολογισμό, έλεγχο ακρίβειας φόρων, δικαιωμάτων και σωστής απόδοσης ποσοστών υπερπρομήθειας. | G9: Συνδέεται 1-προς-1 με UATOP613 (Συμβαλλόμενος), 1-προς-Ν με UATOP614 (Ασφαλισμένοι) και 1-προς-Ν με UATOP615 (Καλύψεις) μέσω του πεδίου F612KLEIDI.
A10: 1411-UATOP613_MONTH_DD_MM_2026.csv | B10: Μητρώο Στοιχείων Συμβαλλομένων / Πελατών | C10: Αναλυτικά δημογραφικά, επικοινωνίας και φορολογικά στοιχεία των πελατών/συμβαλλομένων. | D10: Μηνιαία | E10: Ονοματεπώνυμο, ΑΦΜ, ΔΟΥ, Διεύθυνση, Πόλη, Τ.Κ., Τηλέφωνα επικοινωνίας (Κινητό/Σταθερό), Email, Αριθμός Ταυτότητας (ΑΔΤ), IBAN. | F10: Χρήση για CRM, ταυτοποίηση πελατών, αποστολή ειδοποιητηρίων και φορολογικό έλεγχο. | G10: Συνδέεται με UATOP612 μέσω του κλειδιού F613KLEIDI και Αρ. Συμβολαίου.
A11: 1411-UATOP614_MONTH_DD_MM_2026.csv | B11: Μητρώο Ασφαλισμένων Προσώπων & Εξαρτωμένων Μελών | C11: Στοιχεία όλων των φυσικών προσώπων που καλύπτονται από το κάθε ασφαλιστήριο συμβόλαιο (κυρίως ασφαλισμένος, σύζυγος, τέκνα). | D11: Μηνιαία | E11: Ονοματεπώνυμο Ασφαλισμένου, Ημερομηνία Γέννησης, Φύλο, Σχέση με τον Συμβαλλόμενο (Κυρίως Ασφαλισμένος, Σύζυγος, Τέκνο), Α/Α Εξαρτώμενου. | F11: Απαραίτητο για τον έλεγχο ορίων ηλικίας, προϋποθέσεων εισόδου/ανανέωσης και διασταύρωση παροχών υγείας. | G11: Συνδέεται με UATOP612 και UATOP615 μέσω του κλειδιού F614KLEIDI.
A12: 1411-UATOP615_MONTH_DD_MM_2026.csv | B12: Αναλυτικό Μητρώο Καλύψεων & Προγραμμάτων (Coverages Ledger) | C12: Καταγραφή κάθε επιμέρους κάλυψης ανά συμβόλαιο με τα δικά της ασφάλιστρα, κεφάλαια, απαλλαγές και προμήθειες. | D12: Μηνιαία | E12: F615PER (Περιγραφή Κάλυψης π.χ. Health Care Superior €1.500, Ασφάλιση Ζωής), F615KAL (Κωδικός Κάλυψης), F615KEK (Κεφάλαιο Κάλυψης), F615PAPASU (Ποσό Απαλλαγής), F615ASK (Καθαρό Ασφάλιστρο), F615PROM (Προμήθεια). | F12: Επιτρέπει τον ακριβή έλεγχο των καλύψεων κάθε συμβολαίου (ποια απαλλαγή επελέγη, ποιο νοσοκομειακό πρόγραμμα, ποιες συμπληρωματικές καλύψεις ζωής υπάρχουν). | G12: Συνδέεται με UATOP612 μέσω του F615KLEIDI.
A13: __57.pdf | B13: Καρτέλα Λογαριασμού 57 (Τρεχούμενος Λογαριασμός ERGO) | C13: Επίσημη τραπεζική/οικονομική καρτέλα της ERGO όπου αποτυπώνονται όλες οι αποδεσμεύσεις προμηθειών & υπερπρομηθειών (Ζωής, Υγείας, Γενικών Κλάδων) και οι πληρωμές. | D13: Μηνιαία | E13: Ημερομηνία Κίνησης, Περιγραφή (Αποδέσμευση αμοιβών Ζωής & Υγείας, Αποδέσμευση προμήθειας/υπερπρομ.), Χρέωση, Πίστωση, Τελικό Υπόλοιπο. | F13: Χρησιμεύει για την τελική ταμειακή συμφωνία (Reconciliation): Η εκκαθάριση του Μήνα Μ πιστώνεται στον Λογαριασμό 57 τον Μήνα Μ+1. | G13: Συνδέεται άμεσα με τα Φύλλα 5 & 6 για έλεγχο απόλυτης ταύτισης αποδεσμεύσεων (Φύλλο 10).
A16: Β. ΛΕΞΙΚΟ ΤΕΧΝΙΚΩΝ ΠΕΔΙΩΝ & ΣΤΗΛΩΝ (DATA DICTIONARY)
A17: Όνομα Πεδίου (Field Name) | B17: Ελληνική Ονομασία / Τίτλος | C17: Περιγραφή & Σημασία | D17: Πού Εμφανίζεται (Αρχεία) | E17: Παράδειγμα Τιμής | F17: Ρόλος στον Υπολογισμό Προμηθειών & Ασφαλίστρων
A18: F612SYM | B18: Αριθμός Συμβολαίου | C18: Ο μοναδικός 10-ψήφιος κωδικός αριθμός του ασφαλιστηρίου συμβολαίου στην ERGO. | D18: UATOP 612-615, Μητρώο, Πινάκιο, Προμήθειες | E18: 2026000765 | F18: Κύριο αναγνωριστικό συμβολαίου.
A19: F612APD | B19: Αριθμός Απόδειξης / Ειδοποίησης | C19: Ο αριθμός της εκδοθείσας απόδειξης πληρωμής / ειδοποιητηρίου ασφαλίστρων. | D19: UATOP 612-615, Μητρώο, Πινάκιο, Προμήθειες | E19: 126897 / 80430703 | F19: Κύριο αναγνωριστικό περιόδου πληρωμής.
A20: F612KLEIDI | B20: Κλειδί Εγγραφής (Master Record Key) | C20: Σύνθετο κλειδί που ενώνει Συμβόλαιο + Απόδειξη + Κωδικό Κίνησης (π.χ. 20260007650000126897...). | D20: UATOP 612, 613, 614, 615 | E20: 202600076500001268970000000000 | F20: Εξασφαλίζει 100% αλάνθαστη συσχέτιση όλων των UATOP αρχείων.
A21: F613EPO1 / F613ONO1 | B21: Ονοματεπώνυμο Συμβαλλομένου | C21: Το πλήρες ονοματεπώνυμο του λήπτη ασφάλισης / πελάτη. | D21: UATOP613 | E21: ΠΑΛΙΑΤΣΑΣ ΑΘΑΝΑΣΙΟΣ | F21: Ταυτοποίηση πελάτη.
A22: F613AFM1 / F613AFM2 | B22: ΑΦΜ Πελάτη / Εταιρείας | C22: Ο Αριθμός Φορολογικού Μητρώου του πελάτη ή της συμβαλλόμενης εταιρείας. | D22: UATOP613 | E22: 135971330 / 800769452 | F22: Φορολογική ταυτοποίηση.
A23: F613KNT1 / F613EMA1 | B23: Κινητό Τηλέφωνο & Email | C23: Τα κύρια στοιχεία άμεσης επικοινωνίας του πελάτη. | D23: UATOP613 | E23: 6947904961 / THANASISPALIATSAS@GMAIL.COM | F23: Επικοινωνία & εξυπηρέτηση.
A24: F613ADO1 / F613APO1 | B24: Διεύθυνση, Πόλη & ΤΚ | C24: Η πλήρης ταχυδρομική διεύθυνση του πελάτη. | D24: UATOP613 | E24: Αιτωλικού 98, Μεσολόγγι ΤΚ 30200 | F24: Αποστολή εγγράφων.
A25: F612MIK | B25: Μικτά Ασφάλιστρα (Gross Premium) | C25: Το τελικό συνολικό ποσό πληρωμής από τον πελάτη (καθαρά + δικαιώματα + φόροι). | D25: UATOP612, Μητρώο, Πινάκιο | E25: € 817.80 | F25: Το ποσό είσπραξης από τον πελάτη.
A26: F612ASK | B26: Καθαρά Ασφάλιστρα (Net Premium) | C26: Το καθαρό ασφάλιστρο κινδύνου της περιόδου. Αποτελεί τη βάση υπολογισμού όλων των προμηθειών. | D26: UATOP612, 615, Προμήθειες | E26: € 666.12 | F26: Βάση Υπολογισμού: Προμήθειες = ASK * %.
A27: F612DIK | B27: Δικαίωμα Συμβολαίου (Policy Fee) | C27: Το πάγιο διαχειριστικό δικαίωμα έκδοσης του συμβολαίου (π.χ. €45, €15, €11.59). | D27: UATOP612, Μητρώο, Πινάκιο | E27: € 45.00 | F27: Προστίθεται στο καθαρό για τη διαμόρφωση του μικτού.
A28: F612FKE | B28: Φόρος Ασφαλίστρων | C28: Ο νόμιμος φόρος κύκλου εργασιών / ασφαλίστρων. | D28: UATOP612, Μητρώο | E28: € 106.68 | F28: Φορολογική επιβάρυνση επί του ασφαλίστρου.
... A31: F615PER | B31: Περιγραφή Κάλυψης Προγράμματος | C31: Η επίσημη ονομασία του ασφαλιστικού προγράμματος και της επιμέρους κάλυψης. | D31: UATOP615 | E31: ERGO HEALTH CARE SUPERIOR € 1.500 | F31: Προσδιορίζει το ασφαλιστικό προϊόν και τον συντελεστή προμήθειας.

Sheet 2. ΠΡΟΪΟΝΤΑ & ΚΑΛΥΨΕΙΣ
A1: ΚΑΤΑΛΟΓΟΣ ΑΣΦΑΛΙΣΤΙΚΩΝ ΠΡΟΪΟΝΤΩΝ & ΚΑΛΥΨΕΩΝ ERGO (ΔΑΣ)
A2: Αναλυτική Χαρτογράφηση Καλύψεων, Ορίων, Απαλλαγών, Θέσεων Νοσηλείας & Ειδικών Παροχών από τα Επίσημα Έγγραφα (IPIDs & Πλοηγός)
A4: 1. ΠΡΟΓΡΑΜΜΑΤΑ ΝΟΣΟΚΟΜΕΙΑΚΗΣ & ΕΞΩΝΟΣΟΚΟΜΕΙΑΚΗΣ ΠΕΡΙΘΑΛΨΗΣ (ΥΓΕΙΑ)
A5: Πρόγραμμα / Κλάδος | B5: Κωδικός Προγράμματος | C5: Ανώτατο Όριο Κάλυψης (€) | D5: Επιλογές Απαλλαγής (€) | E5: Θέση Νοσηλείας | F5: Καλύψεις & Ειδικές Παροχές | G5: Κάλυψη Εξωτερικού & Ειδικοί Όροι
A6: ERGO Health Care Simple | B6: 020118 - 020318 | C6: € 300,000 ανά περιστατικό & ανά έτος | D6: € 500 / € 1,500 / € 3,000 | E6: Β' Θέση (Δίκλινο) | F6: Νοσοκομειακή περίθαλψη 100% μετά την απαλλαγή σε συμβεβλημένα νοσηλευτήρια, ΜΕΘ/ΜΑΦ 100%, Χειρουργικές επεμβάσεις, Αμοιβές ιατρών/χειρουργών, Επείγοντα περιστατικά έως €500/περιστατικό, Χημειοθεραπείες / Ακτινοθεραπείες χωρίς απαλλαγή, Χειρουργικό επίδομα. | G6: Κάλυψη στην Ευρώπη και παγκοσμίως (εκτός ΗΠΑ/Καναδά με 80% συμμετοχή εταιρείας). Απευθείας διακανονισμός στο συμβεβλημένο δίκτυο ERGO.
A7: ERGO Health Care Advanced | B7: 020418 - 020618 | C7: € 500,000 ανά περιστατικό & ανά έτος | D7: € 500 / € 1,500 / € 3,000 | E7: Α' Θέση (Μονόκλινο) | F7: Πλήρης κάλυψη νοσηλείας 100% μετά την απαλλαγή, ΜΕΘ/ΜΑΦ χωρίς όριο, Προ-νοσοκομειακά και μετα-νοσοκομειακά έξοδα (έως 60 ημέρες πριν & 90 ημέρες μετά), Έξοδα συνοδού για παιδιά, Αποκλειστική νοσοκόμα, Επείγουσα υγειονομική μεταφορά (Ασθενοφόρο/Αερομεταφορά), Ειδικά επιδόματα τοκετού & χειρουργικής επέμβασης. | G7: Κάλυψη στην Ευρώπη & Παγκόσμια (με ΗΠΑ/Καναδά 80%-90%). Απευθείας κάλυψη στα μεγαλύτερα ιδιωτικά θεραπευτήρια.
A8: ERGO Health Care Superior | B8: 020718 - 021118 | C8: € 1,000,000 ανά περιστατικό & ανά έτος | D8: € 500 / € 1,500 / € 3,000 | E8: Lux / Α' Θέση (Μονόκλινο/Σουίτα) | F8: Κορυφαία κάλυψη VIP, 100% έξοδα νοσηλείας, Πλήρης κάλυψη ρομποτικής χειρουργικής, Ειδικά μοσχεύματα, Προηγμένες θεραπείες καρκίνου & βιολογικοί παράγοντες, Αποκατάσταση μαστού μετά από μαστεκτομή, Επίδομα μη χρήσης ασφαλιστηρίου έως €1.500, Ψυχολογική υποστήριξη. | G8: Πλήρης παγκόσμια κάλυψη 100% (και σε ΗΠΑ/Καναδά). Ειδική γραμμή υγείας ERGO 24/7.
A9: ERGO Best Health | B9: 020119 - 021619 | C9: € 300,000 - € 600,000 | D9: € 0 / € 500 / € 1,500 | E9: Β' / Α' Θέση | F9: Συνδυαστικό πρόγραμμα νοσοκομειακής & εξωνοσοκομειακής προστασίας με προνομιακή τιμολόγηση. Περιλαμβάνει κάλυψη εξόδων νοσηλείας και πρωτοβάθμιας περίθαλψης. | G9: Ισχύει σε πανελλαδικό δίκτυο συμβεβλημένων κλινικών.
A10: ERGO Affidea & Εξωνοσοκομειακά / Διαγνωστικά | B10: 020121, 020221, 021722 | C10: Απεριόριστες Επισκέψεις & Εξετάσεις | D10: € 0 (Μηδενική Απαλλαγή) | E10: Εξωτερικά Ιατρεία / Διαγνωστικά Κέντρα | F10: Απεριόριστες διαγνωστικές εξετάσεις σε δίκτυο Affidea / Medisystem, Ετήσιο προληπτικό Check-Up (πλήρες), Απεριόριστες επισκέψεις σε ιατρούς βασικών ειδικοτήτων (Παθολόγος, Καρδιολόγος, Χειρουργός, Ορθοπεδικός, Οφθαλμίατρος), Έκπτωση σε φυσικοθεραπείες και οδοντιατρικές πράξεις. | G10: Άμεση πρόσβαση χωρίς παραπεμπτικό ΕΟΠΥΥ ή με χρήση ΕΟΠΥΥ για μηδενική συμμετοχή.
A13: 2. ΠΡΟΓΡΑΜΜΑΤΑ ΑΣΦΑΛΙΣΗΣ ΖΩΗΣ & ΣΥΜΠΛΗΡΩΜΑΤΙΚΕΣ ΚΑΛΥΨΕΙΣ (LIFE)
A14: Πρόγραμμα / Κάλυψη Ζωής | B14: Κωδικός Κάλυψης | C14: Φύση Κάλυψης | D14: Εύρος Ασφαλισμένου Κεφαλαίου (€) | E14: Ηλικίες Εισόδου / Λήξης | F14: Παροχή & Τρόπος Καταβολής | G14: Ειδικοί Όροι & Συνδυασμοί
A15: Βασική Ασφάλιση Ζωής (Ισόβια) | B15: 110118 | C15: Βασική Ασφάλιση Ζωής | D15: € 10,000 έως € 1,000,000+ | E15: 18 - 65 ετών / Ισόβια | F15: Καταβολή του ασφαλισμένου κεφαλαίου στους ορισθέντες δικαιούχους σε περίπτωση απώλειας ζωής του ασφαλισμένου από οποιαδήποτε αιτία (ασθένεια ή ατύχημα). | G15: Απαλλαγμένο από φόρο κληρονομιάς. Δυνατότητα προσθήκης συμπληρωματικών καλύψεων.
A16: Πρόσκαιρη Ασφάλιση Ζωής (Term Life) | B16: 110218, 110318 | C16: Πρόσκαιρη Ασφάλιση Ορισμένης Διάρκειας | D16: € 15,000 έως € 2,000,000+ | E16: 18 - 65 ετών / Έως 75 ετών | F16: Καταβολή κεφαλαίου σε περίπτωση θανάτου κατά τη διάρκεια της ασφαλιστικής περιόδου (π.χ. 10, 15, 20, 25 έτη ή κάλυψη δανείου). | G16: Χαμηλό κόστος ασφαλίστρου. Ιδανικό για κάλυψη στεγαστικών δανείων και προστασία οικογένειας.
A17: Θάνατος από Ατύχημα (ΘΑ) | B17: 130118 | C17: Συμπληρωματική Κάλυψη Ατυχήματος | D17: € 10,000 έως € 500,000 | E17: 18 - 65 ετών / Έως 70 ετών | F17: Καταβολή επιπλέον κεφαλαίου στους δικαιούχους σε περίπτωση απώλειας ζωής αποκλειστικά από ατύχημα (διπλασιασμός κεφαλαίου αν συνδυάζεται με βασική ζωή). | G17: Άμεση καταβολή χωρίς αναμονές.
A18: Μόνιμη Ολική / Μερική Ανικανότητα (ΜΟΑ / ΜΜΑ) | B18: 130218 | C18: Συμπληρωματική Κάλυψη Ανικανότητας | D18: € 10,000 έως € 500,000 | E18: 18 - 60 ετών / Έως 65 ετών | F18: Καταβολή εφάπαξ ποσού ανάλογα με το ποσοστό ανικανότητας (πίνακας Continental Scale) σε περίπτωση ανικανότητας για εργασία από ατύχημα. | G18: Προστασία εισοδήματος και επαγγελματικής ικανότητας.
A19: Απώλεια Εισοδήματος από Ατύχημα ή Ασθένεια | B19: 130318 | C19: Μηνιαίο Επίδομα | D19: € 500 έως € 3,000 / μήνα | E19: 18 - 60 ετών / Έως 65 ετών | F19: Καταβολή μηνιαίου επιδόματος για όσο διάστημα ο ασφαλισμένος αδυνατεί να ασκήσει το επάγγελμά του (έως 12 ή 24 μήνες). | G19: Απαραίτητο για ελεύθερους επαγγελματίες και αυτοαπασχολούμενους.
A20: Απαλλαγή Πληρωμής Ασφαλίστρων (ΑΠΑ) | B20: 110418 | C20: Προστασία Συμβολαίου | D20: Ισόποσο με το Ετήσιο Ασφάλιστρο | E20: 18 - 55 ετών / Έως 65 ετών | F20: Σε περίπτωση Μόνιμης Ολικής Ανικανότητας του συμβαλλομένου, η ERGO αναλαμβάνει την πληρωμή όλων των μελλοντικών ασφαλίστρων του συμβολαίου. | G20: Διασφαλίζει ότι το συμβόλαιο υγείας και αποταμίευσης παραμένει σε πλήρη ισχύ.
A23: 3. ΟΜΑΔΙΚΑ ΠΡΟΓΡΑΜΜΑΤΑ & ΑΠΟΤΑΜΙΕΥΤΙΚΑ / ΕΠΕΝΔΥΤΙΚΑ (GROUP & SAVINGS)
A24: Κατηγορία / Προϊόν | B24: Κωδικός Προγράμματος | C24: Τύπος Προγράμματος | D24: Ελάχιστη Καταβολή / Κεφάλαιο | E24: Καλύψεις & Παροχές | F24: Επενδυτική Πολιτική / Εγγύηση | G24: Προμήθεια Παραγωγού
A25: Ομαδική Ασφάλιση Προσωπικού (ERGO MY PEOPLE) | B25: Group Life & Health | C25: Ομαδικό Συμβόλαιο Επιχειρήσεων | D25: Ελάχιστο 5 ασφαλισμένοι | E25: Κάλυψη Απώλειας Ζωής, Μόνιμης Ανικανότητας, Νοσοκομειακής Περίθαλψης, Εξωνοσοκομειακών εξετάσεων, Check-up, Επίδομα μητρότητας. | F25: Ετήσιο ανανεούμενο συμβόλαιο με φορολογική έκπτωση 100% για την επιχείρηση. | G25: 8.00% - 15.00% επί των καθαρών ασφαλίστρων.
A26: ERGO My Saving Simple | B26: 990119, 990219 | C26: Εγγυημένο Αποταμιευτικό Πρόγραμμα | D26: Ελάχιστο €50 / μήνα (€600 / έτος) | E26: Εγγυημένο κεφάλαιο στη λήξη, Εγγυημένη ελάχιστη απόδοση, Προστασία κεφαλαίου 100%, Δυνατότητα έκτακτων καταβολών, Δικαίωμα εξαγοράς μετά το 2ο έτος. | F26: Επενδύσεις χαμηλού ρίσκου σε ομόλογα υψηλής διαβάθμισης με εγγυημένο επιτόκιο. | G26: 14.58% - 17.50% (1ο έτος), 6.67% - 8.00% (2ο), 4.17% - 5.00% (3ο).
A27: ERGO My Fund Flex Plan (Unit Linked) | B27: 030122 | C27: Επενδυτικό Τακτικών Καταβολών | D27: Ελάχιστο €40 / μήνα (€480 / έτος) | E27: Δημιουργία κεφαλαίου μέσω επένδυσης σε κορυφαία διεθνή αμοιβαία κεφάλαια (MEAG / Munich Re Group), Ευελιξία αλλαγής επενδυτικού προφίλ, Έκτακτες καταβολές. | F27: Επιλογή προφίλ: Συντηρητικό, Ισορροπημένο, Δυναμικό. Σύνδεση με διεθνείς αγορές. | G27: 18.33% - 26.50% (1ο έτος), 6.67% - 18.00% (2ο), 1.67% - 4.00% (3ο).
A28: ERGO My Fund Invest Plan (Single Premium) | B28: 030222 | C28: Επενδυτικό Εφάπαξ Καταβολής | D28: Ελάχιστο €4,000 εφάπαξ | E28: Επένδυση κεφαλαίου σε παγκόσμια χαρτοφυλάκια της Munich Re με ευελιξία μερικής ή ολικής ρευστοποίησης, φορολογικά πλεονεκτήματα ασφαλιστηρίου. | F28: Διαχείριση από την MEAG (Asset Manager της Munich Re & ERGO). | G28: 1.17% - 1.70% εφάπαξ προμήθεια.

Sheet 3. ΠΡΟΜΗΘΕΙΕΣ & ΥΠΕΡΠΡΟΜΗΘΕΙΕΣ
A1: ΕΠΙΣΗΜΟΙ ΠΙΝΑΚΕΣ ΠΡΟΜΗΘΕΙΩΝ, ΥΠΕΡΠΡΟΜΗΘΕΙΩΝ ΔΙΚΤΥΟΥ & BONUS ERGO (ΔΑΣ)
A2: Πλήρης Ανάλυση Κανονισμού Πωλήσεων: Βαθμίδες Συνεργατών Α/Β/Γ, Προμήθειες 1ου Έτους & Ανανεώσεων, Υπερπρομήθειες Agency 1411 (LANCA Ε.Ε.) & Bonus
A4: Α. ΚΑΤΗΓΟΡΙΕΣ & ΚΡΙΤΗΡΙΑ ΕΝΤΑΞΗΣ ΣΥΝΕΡΓΑΤΩΝ (PARTNER TIERS)
A5: Κατηγορία Συνεργάτη | B5: Όριο Νέας Ετήσιας Παραγωγής Καθαρών (€) | C5: Όριο Συνολικού Χαρτοφυλακίου (€) | D5: Συντελεστής Επίδοσης | E5: Προνόμια & Κλίμακα
A6: Κατηγορία Α (Category A) | B6: Έως € 10,000 | C6: Έως € 50,000 | D6: 1.00x (Βασική Κλίμακα) | E6: Βασικοί συντελεστές προμηθειών 1ου έτους και ανανεώσεων.
A7: Κατηγορία Β (Category B) | B7: € 10,001 έως € 20,000 | C7: € 50,001 έως € 100,000 | D7: 1.10x (+10% Προσαύξηση) | E7: Αυξημένες προμήθειες 1ου έτους (+10% σε σχέση με την Κατ. Α) & αυξημένες ανανεώσεις.
A8: Κατηγορία Γ (Category C) | B8: Άνω των € 20,000 | C8: Άνω των € 100,000 | D8: 1.20x (+20% Προσαύξηση) | E8: Μέγιστη κλίμακα προμηθειών 1ου έτους (+20% σε σχέση με την Κατ. Α), μέγιστες ανανεώσεις και επιπλέον Bonus.
A11: Β. ΠΙΝΑΚΑΣ ΠΡΟΜΗΘΕΙΩΝ ΠΑΡΑΓΩΓΟΥ ΑΝΑ ΚΛΑΔΟ & ΕΤΟΣ ΣΥΜΒΟΛΑΙΟΥ (% επί Καθαρών Ασφαλίστρων)
A12: Κλάδος / Ασφαλιστικό Πρόγραμμα | B12: Κωδικός | C12: 1ο Έτος (Κατ. Α) | D12: 1ο Έτος (Κατ. Β) | E12: 1ο Έτος (Κατ. Γ) | F12: 2ο Έτος (Ανανέωση) | G12: 3ο Έτος (Ανανέωση) | H12: 4ο+ Έτος (Ανανέωση)
A13: ERGO Health Care (Simple, Advanced, Superior) | B13: 020118-021118 | C13: 0.29 | D13: 0.319 | E13: 0.348 | F13: 0.25 | G13: 0.25 | H13: 0.25
A14: ERGO Best Health | B14: 020119-021619 | C14: 0.26 | D14: 0.286 | E14: 0.312 | F14: 0.23 | G14: 0.23 | H14: 0.23
A15: Affidea / Εξωνοσοκομειακά / Διαγνωστικά | B15: 020121-020221 | C15: 0.27 | D15: 0.29 | E15: 0.31 | F15: 0.27 | G15: 0.27 | H15: 0.27
A16: ERGO Διαγνωστικό | B16: 021722-021822 | C16: 0.3 | D16: 0.33 | E16: 0.36 | F16: 0.3 | G16: 0.3 | H16: 0.3
A17: Ισόβια / Πρόσκαιρη Ασφάλιση Ζωής | B17: 110118-110218 | C17: 0.5 | D17: 0.55 | E17: 0.6 | F17: 0.15 | G17: 0.08 | H17: 0.05
A18: Ασφάλιση Ζωής (Standard) | B18: 110318 | C18: 0.25 | D18: 0.275 | E18: 0.3 | F18: 0.2 | G18: 0.12 | H18: 0.06
A19: Θάνατος από Ατύχημα (ΘΑ) | B19: 130118 | C19: 0.3 | D19: 0.33 | E19: 0.36 | F19: 0.3 | G19: 0.3 | H19: 0.3
A20: Μόνιμη Ολική / Μερική Ανικανότητα (ΜΟΑ) | B20: 130218 | C20: 0.275 | D20: 0.303 | E20: 0.33 | F20: 0.275 | G20: 0.275 | H20: 0.275
A21: Απώλεια Εισοδήματος από Ατύχημα | B21: 130318 | C21: 0.3 | D21: 0.33 | E21: 0.36 | F21: 0.3 | G21: 0.3 | H21: 0.3
A22: Ιατροφαρμακευτικά Έξοδα Ατυχήματος | B22: 130418 | C22: 0.3 | D22: 0.33 | E22: 0.36 | F22: 0.3 | G22: 0.3 | H22: 0.3
A23: Απαλλαγή Πληρωμής Ασφαλίστρων (ΑΠΑ) | B23: 110418 | C23: 0.25 | D23: 0.275 | E23: 0.305 | F23: 0.2 | G23: 0.12 | H23: 0.06
A24: ERGO My Saving Simple (Αποταμίευση) | B24: 990119-990219 | C24: 0.1458 | D24: 0.1604 | E24: 0.175 | F24: 0.0667 | G24: 0.0417 | H24: 0
... A27: Ομαδικά Ασφαλιστήρια (ERGO My People) | B27: Group | C27: 0.08 | D27: 0.1 | E27: 0.15 | F27: 0.08 | G27: 0.08 | H27: 0.08
A30: Γ. ΔΟΜΗ ΥΠΕΡΠΡΟΜΗΘΕΙΩΝ ΔΙΚΤΥΟΥ & ΓΡΑΦΕΙΟΥ 1411 (LANCA Ε.Ε.)
A31: Βαθμίδα Οργανωτικής Μονάδας | B31: Ποσοστό Υπερπρομήθειας (%) | C31: Βάση Υπολογισμού | D31: Ισοδύναμο % επί Καθαρών Ασφαλίστρων (Ενδεικτικά για Υγεία 29%) | E31: Δικαιούχος & Τρόπος Απόδοσης | F31: Συμπεριφορά σε Υποκωδικό Συνεργάτη vs Direct Γραφείου 1411
A32: Unit Manager (Ομαδάρχης) | B32: 0.1 | C32: Επί της Βασικής Προμήθειας Παραγωγού (PPO) | D32: 2.90% επί των καθαρών ασφαλίστρων (10% * 29%) | E32: Πιστώνεται στον Unit Manager της ομάδας για την παραγωγή των μελών του. | F32: Εάν υπάρχει Unit Manager στην ιεραρχία του συνεργάτη, λαμβάνει 10% επί της προμήθειας.
A33: Agency Manager / Γραφείο 1411 (LANCA Ε.Ε.) | B33: 0.2 | C33: Επί της Βασικής Προμήθειας Παραγωγού (PPO) | D33: 5.80% επί των καθαρών ασφαλίστρων (20% * 29%) | E33: Πιστώνεται στο Agency 1411 (LANCA Ε.Ε.) για όλη την παραγωγή του δικτύου. | F33: Σε παραγωγή συνεργάτη με Υποκωδικό: Το Γραφείο 1411 εισπράττει την πλήρη Υπερπρομήθεια 20% (F612PAG). Εάν δεν υπάρχει Unit, το Agency παίρνει ολόκληρο το 20%.
A34: Direct Παραγωγή Γραφείου 1411 (House Business) | B34: 1.2 | C34: 100% Προμήθεια Παραγωγού + 20% Υπερπρομήθεια Agency | D34: 34.80% επί των καθαρών ασφαλίστρων (29% + 5.8%) | E34: Πιστώνεται εξ ολοκλήρου στο Γραφείο 1411 (LANCA Ε.Ε.). | F34: Στα συμβόλαια που εκδίδονται απευθείας στον κωδικό 1411 (χωρίς εξωτερικό συνεργάτη), το γραφείο εισπράττει τόσο την αμοιβή παραγωγού όσο και την υπερπρομήθεια δικτύου!
A37: Δ. ΕΤΗΣΙΑ BONUS ΔΙΑΤΗΡΗΣΗΣ, ΑΠΟΤΕΛΕΣΜΑΤΟΣ & ΝΕΑΣ ΠΑΡΑΓΩΓΗΣ
A38: Τύπος Bonus | B38: Κριτήριο & Κλίμακα Επίδοσης | C38: Ποσοστό Bonus (%) | D38: Βάση Υπολογισμού | E38: Σημειώσεις & Προϋποθέσεις
A39: Bonus Διατήρησης & Ανάπτυξης Χαρτοφυλακίου | B39: Χαρτοφυλάκιο > €50,000 Χαρτοφυλάκιο > €100,000 Χαρτοφυλάκιο > €150,000 | C39: 1.00% 1.50% 2.00% | D39: Εισπραγμένα καθαρά ασφάλιστρα Ζωής & Υγείας | E39: Καταβάλλεται ετησίως επί του συνόλου του χαρτοφυλακίου.
A40: Bonus Καλού Αποτελέσματος (Loss Ratio) | B40: Loss Ratio (S/P) <= 50% Loss Ratio (S/P) <= 45% Loss Ratio (S/P) <= 40% Loss Ratio (S/P) <= 35% Loss Ratio (S/P) <= 30% | C40: 2.00% 3.00% 4.00% 5.00% 6.00% | D40: Ετήσια δεδουλευμένα καθαρά ασφάλιστρα Υγείας | E40: Ελάχιστη παραγωγή καθαρών ασφαλίστρων €30,000.
A41: Bonus Πρωτοετούς Παραγωγής Υγείας | B41: Νέα Παραγωγή > €10,000 Νέα Παραγωγή > €20,000 Νέα Παραγωγή > €30,000 Νέα Παραγωγή > €40,000 Νέα Παραγωγή > €50,000 | C41: 1.00% 2.00% 3.00% 4.00% 5.00% | D41: Εισπραγμένη νέα παραγωγή καθαρών ασφαλίστρων Υγείας | E41: Επιβράβευση ανάπτυξης νέων εργασιών.
A42: Bonus Διατηρησιμότητας (Persistency) | B42: Διατηρησιμότητα 80% - 85% Διατηρησιμότητα 85% - 90% Διατηρησιμότητα > 90% | C42: 5.00% - 7.00% 9.00% 13.50% | D42: Επί των προμηθειών ανανεώσεων | E42: Υπολογίζεται στις 31/12 για συμβόλαια που ανανεώθηκαν επιτυχώς.

Sheet 4. ΔΙΑΔΡΑΣΤΙΚΟΣ ΥΠΟΛΟΓΙΣΤΗΣ
A1: ΔΙΑΔΡΑΣΤΙΚΟΣ ΥΠΟΛΟΓΙΣΤΗΣ ΑΣΦΑΛΙΣΤΡΩΝ, ΠΡΟΜΗΘΕΙΩΝ & ΥΠΕΡΠΡΟΜΗΘΕΙΩΝ
A2: Εισάγετε τα στοιχεία του συμβολαίου στα κίτρινα πεδία για να υπολογιστούν αυτόματα οι προμήθειες συνεργάτη και οι υπερπρομήθειες του γραφείου 1411 (LANCA Ε.Ε.)
B4: ΣΤΟΙΧΕΙΑ ΕΙΣΑΓΩΓΗΣ (USER INPUTS) | E4: ΑΠΟΤΕΛΕΣΜΑΤΑ ΥΠΟΛΟΓΙΣΜΟΥ (OUTPUTS)
B5: Κλάδος / Ασφαλιστικό Πρόγραμμα: | C5: ERGO Health Care | E5: Καθαρό Ασφάλιστρο Βάσης (Net Premium): | F5: =C8-C9
B6: Έτος Συμβολαίου: | C6: 1ο Έτος | E6: Βασικός Συντελεστής Προμήθειας Παραγωγού (%): | F6: =IF(C5="ERGO Health Care", IF(C6="1ο Έτος", IF(C7="Κατηγορία Α", 29%, IF(C7="Κατηγορία Β", 31.9%, 34.8%)), 25%), IF(C5="ERGO Best Health", IF(C6="1ο Έτος", 26%, 23%), IF(C5="Ισόβια / Πρόσκαιρη Ζωής", IF(C6="1ο Έτος", 50%, IF(C6="2ο Έτος", 15%, 8%)), IF(C5="ERGO My Saving Simple", IF(C6="1ο Έτος", 14.58%, 6.67%), 25%))))
B7: Κατηγορία Συνεργάτη: | C7: Κατηγορία Α | E7: Συνολική Βασική Προμήθεια Παραγωγού (€): | F7: =ROUND(F5*F6, 2)
B8: Μικτά Ασφάλιστρα (€): | C8: 817.8 | E8: Ποσό Πληρωμής στον Συνεργάτη (€): | F8: =IF(C10="Direct Γραφείο 1411 (LANCA)", 0, ROUND(F7*C11, 2))
B9: Εκτιμώμενα Δικαιώματα & Φόροι (€): | C9: 151.68 | E9: Υπερπρομήθεια Agency Γραφείου 1411 (20% επί Προμήθειας): | F9: =ROUND(F7*20%, 2)
B10: Τύπος Παραγωγού: | C10: Συνεργάτης με Υποκωδικό | E10: Προμήθεια Direct Γραφείου 1411 (αν Direct): | F10: =IF(C10="Direct Γραφείο 1411 (LANCA)", F7, 0)
B11: Συμφωνηθέν Ποσοστό Συνεργάτη (%): | C11: 1 | E11: Διαφορά / Παρακράτηση Προμήθειας Γραφείου (€): | F11: =ROUND(F7-F8-F10, 2)
E12: ΣΥΝΟΛΙΚΟ ΚΕΡΔΟΣ / ΕΙΣΡΟΗ ΓΡΑΦΕΙΟΥ 1411 (LANCA Ε.Ε.) (€): | F12: =ROUND(F9+F10+F11, 2)
E13: Συνολικό Ποσοστό Απόδοσης Γραφείου επί Καθαρών (%): | F13: =ROUND(F12/F5, 4)
A16: ΠΙΝΑΚΑΣ ΕΝΔΕΙΚΤΙΚΩΝ ΣΕΝΑΡΙΩΝ ΣΥΜΒΟΛΑΙΩΝ & ΑΝΑΛΥΣΗ ΚΕΡΔΟΦΟΡΙΑΣ ΓΡΑΦΕΙΟΥ 1411
A17: Πρόγραμμα Ασφάλισης | B17: Έτος Συμβολαίου | C17: Μικτά Ασφάλιστρα (€) | D17: Καθαρά Ασφάλιστρα (€) | E17: Συντελεστής Προμήθειας (%) | F17: Προμήθεια Συνεργάτη (€) | G17: Υπερπρομήθεια Agency 1411 (€) | H17: Συνολικό Έσοδο 1411 (Direct) | I17: Συνολικό Έσοδο 1411 (Υποκωδικός)
A18: ERGO Health Care Superior (€1.500) | B18: 1ο Έτος | C18: 817.8 | D18: 666.12 | E18: 0.29 | F18: =ROUND(D18*E18, 2) | G18: =ROUND(F18*20%, 2) | H18: =ROUND(F18+G18, 2) | I18: =G18
A19: ERGO Health Care Simple (€500) | B19: 1ο Έτος | C19: 475.5 | D19: 414.55 | E19: 0.29 | F19: =ROUND(D19*E19, 2) | G19: =ROUND(F19*20%, 2) | H19: =ROUND(F19+G19, 2) | I19: =G19
A20: ERGO Health Care Advanced (€500) | B20: Ανανέωση (2ο+) | C20: 475.5 | D20: 414.55 | E20: 0.25 | F20: =ROUND(D20*E20, 2) | G20: =ROUND(F20*20%, 2) | H20: =ROUND(F20+G20, 2) | I20: =G20
A21: ERGO Health Care Advanced (€3.000) | B21: Ανανέωση (2ο+) | C21: 247.37 | D21: 202.37 | E21: 0.25 | F21: =ROUND(D21*E21, 2) | G21: =ROUND(F21*20%, 2) | H21: =ROUND(F21+G21, 2) | I21: =G21
A22: Ασφάλιση Ζωής & Υγείας (FTTB IKE) | B22: 1ο Έτος | C22: 966.6 | D22: 874.16 | E22: 0.2724 | F22: =ROUND(D22*E22, 2) | G22: =ROUND(F22*20%, 2) | H22: =ROUND(F22+G22, 2) | I22: =G22
A23: Ισόβια Ασφάλιση Ζωής | B23: 1ο Έτος | C23: 1200 | D23: 1000 | E23: 0.5 | F23: =ROUND(D23*E23, 2) | G23: =ROUND(F23*20%, 2) | H23: =ROUND(F23+G23, 2) | I23: =G23
A24: Ισόβια Ασφάλιση Ζωής | B24: Ανανέωση (2ο) | C24: 1200 | D24: 1000 | E24: 0.15 | F24: =ROUND(D24*E24, 2) | G24: =ROUND(F24*20%, 2) | H24: =ROUND(F24+G24, 2) | I24: =G24
A25: ERGO My Saving Simple | B25: 1ο Έτος | C25: 1200 | D25: 1000 | E25: 0.1458 | F25: =ROUND(D25*E25, 2) | G25: =ROUND(F25*20%, 2) | H25: =ROUND(F25+G25, 2) | I25: =G25
A26: ERGO My Fund Flex Plan (Unit Linked) | B26: 1ο Έτος | C26: 1500 | D26: 1250 | E26: 0.22 | F26: =ROUND(D26*E26, 2) | G26: =ROUND(F26*20%, 2) | H26: =ROUND(F26+G26, 2) | I26: =G26
A27: Ομαδικό ERGO My People | B27: Ετήσιο | C27: 3500 | D27: 3000 | E27: 0.1 | F27: =ROUND(D27*E27, 2) | G27: =ROUND(F27*20%, 2) | H27: =ROUND(F27+G27, 2) | I27: =G27

Sheet 5. ΕΝΟΠΟΙΗΜΕΝΑ ΔΕΔΟΜΕΝΑ 2026
A1: ΕΝΟΠΟΙΗΜΕΝΟ ΜΗΤΡΩΟ ΠΑΡΑΓΩΓΗΣ, ΑΝΑΝΕΩΣΕΩΝ & ΕΚΚΑΘΑΡΙΣΕΩΝ 2026
A2: Πλήρης Χρονολογική Ενοποίηση Όλων των 20 Οικονομικών Κινήσεων 2026 από τα Αρχεία 1411-ΠΡΟΜΗΘΕΙΕΣ με Πλήρη Στοιχεία Πελατών, Πακέτο, Προμήθειες & Υπερπρομήθειες
A5: Α/Α | B5: Ημερομηνία Έναρξης | C5: Μήνας Εκκαθάρισης | D5: Αρ. Συμβολαίου | E5: Αρ. Απόδειξης | F5: Ονοματεπώνυμο Πελάτη / Επωνυμία | G5: Πακέτο / Πρόγραμμα Ασφάλισης | H5: ΑΦΜ Πελάτη | I5: Τηλέφωνο Επικοινωνίας | J5: Email Πελάτη | K5: Διεύθυνση & Πόλη | L5: Κωδικός Συνεργάτη | M5: Τρόπος Πληρωμής | N5: Διαν. Έτος | O5: Διάρκεια | P5: Μικτά Ασφάλιστρα (€) | Q5: Καθαρά ΒΚ - Ζωή (€) | R5: Καθαρά ΣΚ - Υγεία (€) | S5: Συνολικά Καθαρά (€) | T5: Προμήθεια Συνεργάτη (€) | U5: Προμήθεια % | V5: Υπερπρομήθεια Agency 1411 (€) | W5: Υπερπρομήθεια % | X5: Συνολική Εισροή 1411 (€) | Y5: Τύπος Κίνησης & Σημείωση Συμψηφισμού
A6: 1 | B6: 27/1/2026 | C6: 03/2026 | D6: 2026000161 | E6: 126288 | F6: ΤΕΖΚΟΣΑΡ ΑΓΛΑΙΑ | G6: ERGO Health Care Simple (€500) + Affidea | H6: 141624244 | I6: 6970030570 | J6: hrisafaki@gmail.com | K6: Αφροδίτης 47-49, Παλαιό Φάληρο ΤΚ 17561 | L6: 1411 | M6: Τριμηνιαία | N6: 1 | O6: 1 | P6: 475.5 | Q6: 0 | R6: 414.55 | S6: 414.55 | T6: 116.18 | U6: 0.2802557 | V6: 23.24 | W6: 0.20003443 | X6: 23.24 | Y6: Νέα Παραγωγή (1ο Έτος)
A7: 2 | B7: 29/1/2026 | C7: 02/2026 | D7: 2026000182 | E7: 126309 | F7: ΠΑΠΑΔΑΚΗΣ ΦΑΙΔΩΝ | G7: Ασφάλιση Ζωής & Υγείας | H7: - | I7: - | J7: - | K7: - | L7: 1411 | M7: Ετήσια | N7: 1 | O7: 1 | P7: 896.3 | Q7: 0 | R7: 896.3 | S7: 896.3 | T7: 0 | U7: 0 | V7: 51.99 | W7: 0.2 | X7: 51.99 | Y7: Νέα Παραγωγή (1ο Έτος)
A8: 3 | B8: 2/2/2026 | C8: 04/2026 | D8: 2026000210 | E8: 126337 | F8: ΜΟΥΛΑΚΑΚΗΣ ΓΡΗΓΟΡΙΟΣ (FTTB IKE) | G8: Ασφάλιση Ζωής & Ατυχήματος (Standard Life) | H8: 800769452 | I8: 6948487836 | J8: GMULAKAKIS@GMAIL.COM | K8: Πολυτεχνείου 3, Γάζι ΤΚ 71414 | L8: 1411 | M8: Ετήσια | N8: 1 | O8: 20 | P8: -1029.77 | Q8: -390.36 | R8: -639.41 | S8: -1029.77 | T8: 0 | U8: 0 | V8: -28.52 | W8: 0.2 | X8: -28.52 | Y8: Συμψηφισμός 0,00 € (Αντιλογισμός/Επανέκδοση)
A9: 4 | B9: 2/2/2026 | C9: 04/2026 | D9: 2026000210 | E9: 126337 | F9: ΜΟΥΛΑΚΑΚΗΣ ΓΡΗΓΟΡΙΟΣ (FTTB IKE) | G9: Ασφάλιση Ζωής & Ατυχήματος (Standard Life) | H9: 800769452 | I9: 6948487836 | J9: GMULAKAKIS@GMAIL.COM | K9: Πολυτεχνείου 3, Γάζι ΤΚ 71414 | L9: 1411 | M9: Ετήσια | N9: 1 | O9: 20 | P9: 1029.77 | Q9: 390.36 | R9: 639.41 | S9: 1029.77 | T9: 0 | U9: 0 | V9: 28.52 | W9: 0.2 | X9: 28.52 | Y9: Συμψηφισμός 0,00 € (Αντιλογισμός/Επανέκδοση)
A10: 5 | B10: 14/2/2026 | C10: 03/2026 | D10: 2025000256 | E10: 80404824 | F10: ΒΑΒΑΤΣΙΚΟΣ ΔΗΜΗΤΡΙΟΣ | G10: ERGO Health Care Advanced (€500) | H10: 160251127 | I10: 6985987796 | J10: DIMVAVATSIKOS@GMAIL.COM | K10: Καρπάθου 11, Πειραιάς ΤΚ 18539 | L10: 1411 | M10: Ετήσια | N10: 2 | O10: 1 | P10: 1309.8 | Q10: 0 | R10: 1093.95 | S10: 1093.95 | T10: 265.07 | U10: 0.24230541 | V10: 53.01 | W10: 0.19998491 | X10: 53.01 | Y10: Συμψηφισμός 0,00 € (Αρχική Εγγραφή)
A11: 6 | B11: 14/2/2026 | C11: 03/2026 | D11: 2025000256 | E11: 80404824 | F11: ΒΑΒΑΤΣΙΚΟΣ ΔΗΜΗΤΡΙΟΣ | G11: ERGO Health Care Advanced (€500) | H11: 160251127 | I11: 6985987796 | J11: DIMVAVATSIKOS@GMAIL.COM | K11: Καρπάθου 11, Πειραιάς ΤΚ 18539 | L11: 1411 | M11: Ετήσια | N11: 2 | O11: 1 | P11: -1309.8 | Q11: 0 | R11: -1093.95 | S11: -1093.95 | T11: -265.07 | U11: 0.24230541 | V11: -53.01 | W11: 0.19998491 | X11: -53.01 | Y11: Συμψηφισμός 0,00 € (Ακύρωση/Επανεγγραφή)
A12: 7 | B12: 17/2/2026 | C12: 02/2026 | D12: 2021000340 | E12: 80405097 | F12: ΚΟΥΠΑΛΟΓΛΟΥ ΑΒΑΠΤΙΣΤΟ | G12: ERGO Health Care Advanced | H12: - | I12: - | J12: - | K12: - | L12: 1411 | M12: Ετήσια | N12: 6 | O12: 1 | P12: 359.74 | Q12: 0 | R12: 359.74 | S12: 359.74 | T12: 89.94 | U12: 0.2500139 | V12: 0 | W12: 0 | X12: 0 | Y12: Ανανέωση (6ο Έτος)
A13: 8 | B13: 24/2/2026 | C13: 03/2026 | D13: 2026000457 | E13: 126592 | F13: ΜΟΥΛΑΚΑΚΗΣ ΓΡΗΓΟΡΙΟΣ (FTTB IKE) | G13: Ασφάλιση Ζωής & Ατυχήματος (Standard Life) | H13: 800769452 | I13: 6948487836 | J13: GMULAKAKIS@GMAIL.COM | K13: Πολυτεχνείου 3, Γάζι ΤΚ 71414 | L13: 1411 | M13: Ετήσια | N13: 1 | O13: 20 | P13: 966.6 | Q13: 390.36 | R13: 483.8 | S13: 874.16 | T13: 238.11 | U13: 0.27238721 | V13: 47.63 | W13: 0.2000336 | X13: 47.63 | Y13: Νέα Παραγωγή (1ο Έτος)
A14: 9 | B14: 21/3/2026 | C14: 03/2026 | D14: 296632 | E14: 80409917 | F14: ΚΟΝΤΟΣ ΚΩΝΣΤΑΝΤΙΝΟΣ | G14: Κλασικό Πρόγραμμα Ζωής & Νοσοκομειακό | H14: 124778260 | I14: 6977046967 | J14: - | K14: Συν/ρχη Πλέσσα 84, Καλλιθέα ΤΚ 17674 | L14: 1411 | M14: Τριμηνιαία | N14: 27 | O14: 99 | P14: 252.9 | Q14: 16.57 | R14: 199.54 | S14: 216.11 | T14: 0 | U14: 0 | V14: 0 | W14: 0 | X14: 0 | Y14: Ανανέωση (27ο Έτος)
A15: 10 | B15: 27/3/2026 | C15: 03/2026 | D15: 2022005568 | E15: 80410903 | F15: ΣΑΡΑΦΙΔΟΥ ΕΛΕΝΗ | G15: ERGO My Saving Simple | H15: - | I15: - | J15: - | K15: - | L15: 1411 | M15: Εξαμηνιαία | N15: 4 | O15: 25 | P15: 75 | Q15: 63.92 | R15: 8.97 | S15: 72.89 | T15: 6.18 | U15: 0.084785293 | V15: 0 | W15: 0 | X15: 0 | Y15: Ανανέωση (4ο Έτος)
A16: 11 | B16: 27/3/2026 | C16: 03/2026 | D16: 2025001066 | E16: 80410942 | F16: ΚΑΤΣΙΓΙΑΝΝΑΚΗ ΚΑΛΛΙΟΠΗ | G16: ERGO Health Care Simple | H16: - | I16: - | J16: - | K16: - | L16: 1411 | M16: Τριμηνιαία | N16: 1 | O16: 15 | P16: 160 | Q16: 138.63 | R16: 7 | S16: 145.63 | T16: 0 | U16: 0 | V16: 3.56 | W16: 0.2 | X16: 3.56 | Y16: Νέα Παραγωγή (1ο Έτος)
A17: 12 | B17: 30/3/2026 | C17: 03/2026 | D17: 2025001836 | E17: 80411824 | F17: ΣΤΕΡΓΙΟΥ ΑΒΑΠΤΙΣΤΟ | G17: ERGO Health Care Simple | H17: - | I17: - | J17: - | K17: - | L17: 1411 | M17: Τριμηνιαία | N17: 1 | O17: 1 | P17: 195 | Q17: 0 | R17: 174.8 | S17: 174.8 | T17: 0 | U17: 0 | V17: 9.84 | W17: 0.2 | X17: 9.84 | Y17: Νέα Παραγωγή (1ο Έτος)
... A25: 20 | B25: 27/7/2026 | C25: 07/2026 | D25: 2026000161 | E25: 80430703 | F25: ΤΕΖΚΟΣΑΡ ΑΓΛΑΙΑ | G25: ERGO Health Care Simple (€500) + Affidea | H25: 141624244 | I25: 6970030570 | J25: hrisafaki@gmail.com | K25: Αφροδίτης 47-49, Παλαιό Φάληρο ΤΚ 17561 | L25: 1411 | M25: Τριμηνιαία | N25: 1 | O25: 1 | P25: 475.5 | Q25: 0 | R25: 414.55 | S25: 414.55 | T25: 116.18 | U25: 0.2802557 | V25: 23.24 | W25: 0.20003443 | X25: 23.24 | Y25: Νέα Παραγωγή (1ο Έτος)
A26: ΓΕΝΙΚΑ ΣΥΝΟΛΑ 2026: | P26: =SUM(P6:P25) | Q26: =SUM(Q6:Q25) | R26: =SUM(R6:R25) | S26: =SUM(S6:S25) | T26: =SUM(T6:T25) | U26: =ROUND(T26/S26, 4) | V26: =SUM(V6:V25) | W26: =ROUND(V26/T26, 4) | X26: =SUM(X6:X25)

Sheet 6. ΕΚΚΑΘΑΡΙΣΗ & DASHBOARD
A1: ΜΗΝΙΑΙΑ ΕΚΚΑΘΑΡΙΣΗ & ΟΙΚΟΝΟΜΙΚΟΣ ΠΙΝΑΚΑΣ ΕΛΕΓΧΟΥ (KPI DASHBOARD)
A2: Συγκεντρωτική Οικονομική Αποτίμηση, Ανάλυση Παραγωγής ανά Μήνα και Καθαρά Έσοδα Γραφείου 1411 (LANCA Ε.Ε.) για το 2026
B4: ΣΥΝΟΛΙΚΑ ΜΙΚΤΑ ΑΣΦΑΛΙΣΤΡΑ | D4: ΣΥΝΟΛΙΚΑ ΚΑΘΑΡΑ ΑΣΦΑΛΙΣΤΡΑ | F4: ΣΥΝΟΛΟ ΠΡΟΜΗΘΕΙΩΝ ΣΥΝΕΡΓΑΤΩΝ | H4: ΣΥΝΟΛΟ ΥΠΕΡΠΡΟΜΗΘΕΙΩΝ 1411 (LANCA)
B5: ='5. ΕΝΟΠΟΙΗΜΕΝΑ ΔΕΔΟΜΕΝΑ 2026'!P26 | D5: ='5. ΕΝΟΠΟΙΗΜΕΝΑ ΔΕΔΟΜΕΝΑ 2026'!S26 | F5: ='5. ΕΝΟΠΟΙΗΜΕΝΑ ΔΕΔΟΜΕΝΑ 2026'!T26 | H5: ='5. ΕΝΟΠΟΙΗΜΕΝΑ ΔΕΔΟΜΕΝΑ 2026'!V26
A8: Α. ΣΥΓΚΕΝΤΡΩΤΙΚΟΣ ΠΙΝΑΚΑΣ ΠΑΡΑΓΩΓΗΣ & ΕΚΚΑΘΑΡΙΣΕΩΝ ΑΝΑ ΜΗΝΑ
A9: Μήνας Έτους 2026 | B9: Πλήθος Κινήσεων | C9: Μικτά Ασφάλιστρα (€) | D9: Καθαρά Ασφάλιστρα (€) | E9: Δικαιώματα & Φόροι (€) | F9: Προμήθεια Παραγωγών (€) | G9: Μέση Προμήθεια % | H9: Υπερπρομήθεια Agency 1411 (€) | I9: Υπερπρομήθεια % | J9: Συνολική Εισροή 1411 (€)
A10: 02/2026 | B10: =COUNTIF('5. ΕΝΟΠΟΙΗΜΕΝΑ ΔΕΔΟΜΕΝΑ 2026'!$C$6:$C$25, A10) | C10: =SUMIF('5. ΕΝΟΠΟΙΗΜΕΝΑ ΔΕΔΟΜΕΝΑ 2026'!$C$6:$C$25, A10, '5. ΕΝΟΠΟΙΗΜΕΝΑ ΔΕΔΟΜΕΝΑ 2026'!$P$6:$P$25) | D10: =SUMIF('5. ΕΝΟΠΟΙΗΜΕΝΑ ΔΕΔΟΜΕΝΑ 2026'!$C$6:$C$25, A10, '5. ΕΝΟΠΟΙΗΜΕΝΑ ΔΕΔΟΜΕΝΑ 2026'!$S$6:$S$25) | E10: =C10-D10 | F10: =SUMIF('5. ΕΝΟΠΟΙΗΜΕΝΑ ΔΕΔΟΜΕΝΑ 2026'!$C$6:$C$25, A10, '5. ΕΝΟΠΟΙΗΜΕΝΑ ΔΕΔΟΜΕΝΑ 2026'!$T$6:$T$25) | G10: =IF(D10=0, 0, ROUND(F10/D10, 4)) | H10: =SUMIF('5. ΕΝΟΠΟΙΗΜΕΝΑ ΔΕΔΟΜΕΝΑ 2026'!$C$6:$C$25, A10, '5. ΕΝΟΠΟΙΗΜΕΝΑ ΔΕΔΟΜΕΝΑ 2026'!$V$6:$V$25) | I10: =IF(F10=0, 0, ROUND(H10/F10, 4)) | J10: =SUMIF('5. ΕΝΟΠΟΙΗΜΕΝΑ ΔΕΔΟΜΕΝΑ 2026'!$C$6:$C$25, A10, '5. ΕΝΟΠΟΙΗΜΕΝΑ ΔΕΔΟΜΕΝΑ 2026'!$X$6:$X$25)
A11: 03/2026 | B11: =COUNTIF('5. ΕΝΟΠΟΙΗΜΕΝΑ ΔΕΔΟΜΕΝΑ 2026'!$C$6:$C$25, A11) | C11: =SUMIF('5. ΕΝΟΠΟΙΗΜΕΝΑ ΔΕΔΟΜΕΝΑ 2026'!$C$6:$C$25, A11, '5. ΕΝΟΠΟΙΗΜΕΝΑ ΔΕΔΟΜΕΝΑ 2026'!$P$6:$P$25) | D11: =SUMIF('5. ΕΝΟΠΟΙΗΜΕΝΑ ΔΕΔΟΜΕΝΑ 2026'!$C$6:$C$25, A11, '5. ΕΝΟΠΟΙΗΜΕΝΑ ΔΕΔΟΜΕΝΑ 2026'!$S$6:$S$25) | E11: =C11-D11 | F11: =SUMIF('5. ΕΝΟΠΟΙΗΜΕΝΑ ΔΕΔΟΜΕΝΑ 2026'!$C$6:$C$25, A11, '5. ΕΝΟΠΟΙΗΜΕΝΑ ΔΕΔΟΜΕΝΑ 2026'!$T$6:$T$25) | G11: =IF(D11=0, 0, ROUND(F11/D11, 4)) | H11: =SUMIF('5. ΕΝΟΠΟΙΗΜΕΝΑ ΔΕΔΟΜΕΝΑ 2026'!$C$6:$C$25, A11, '5. ΕΝΟΠΟΙΗΜΕΝΑ ΔΕΔΟΜΕΝΑ 2026'!$V$6:$V$25) | I11: =IF(F11=0, 0, ROUND(H11/F11, 4)) | J11: =SUMIF('5. ΕΝΟΠΟΙΗΜΕΝΑ ΔΕΔΟΜΕΝΑ 2026'!$C$6:$C$25, A11, '5. ΕΝΟΠΟΙΗΜΕΝΑ ΔΕΔΟΜΕΝΑ 2026'!$X$6:$X$25)
A12: 04/2026 | B12: =COUNTIF('5. ΕΝΟΠΟΙΗΜΕΝΑ ΔΕΔΟΜΕΝΑ 2026'!$C$6:$C$25, A12) | C12: =SUMIF('5. ΕΝΟΠΟΙΗΜΕΝΑ ΔΕΔΟΜΕΝΑ 2026'!$C$6:$C$25, A12, '5. ΕΝΟΠΟΙΗΜΕΝΑ ΔΕΔΟΜΕΝΑ 2026'!$P$6:$P$25) | D12: =SUMIF('5. ΕΝΟΠΟΙΗΜΕΝΑ ΔΕΔΟΜΕΝΑ 2026'!$C$6:$C$25, A12, '5. ΕΝΟΠΟΙΗΜΕΝΑ ΔΕΔΟΜΕΝΑ 2026'!$S$6:$S$25) | E12: =C12-D12 | F12: =SUMIF('5. ΕΝΟΠΟΙΗΜΕΝΑ ΔΕΔΟΜΕΝΑ 2026'!$C$6:$C$25, A12, '5. ΕΝΟΠΟΙΗΜΕΝΑ ΔΕΔΟΜΕΝΑ 2026'!$T$6:$T$25) | G12: =IF(D12=0, 0, ROUND(F12/D12, 4)) | H12: =SUMIF('5. ΕΝΟΠΟΙΗΜΕΝΑ ΔΕΔΟΜΕΝΑ 2026'!$C$6:$C$25, A12, '5. ΕΝΟΠΟΙΗΜΕΝΑ ΔΕΔΟΜΕΝΑ 2026'!$V$6:$V$25) | I12: =IF(F12=0, 0, ROUND(H12/F12, 4)) | J12: =SUMIF('5. ΕΝΟΠΟΙΗΜΕΝΑ ΔΕΔΟΜΕΝΑ 2026'!$C$6:$C$25, A12, '5. ΕΝΟΠΟΙΗΜΕΝΑ ΔΕΔΟΜΕΝΑ 2026'!$X$6:$X$25)
A13: 05/2026 | B13: =COUNTIF('5. ΕΝΟΠΟΙΗΜΕΝΑ ΔΕΔΟΜΕΝΑ 2026'!$C$6:$C$25, A13) | C13: =SUMIF('5. ΕΝΟΠΟΙΗΜΕΝΑ ΔΕΔΟΜΕΝΑ 2026'!$C$6:$C$25, A13, '5. ΕΝΟΠΟΙΗΜΕΝΑ ΔΕΔΟΜΕΝΑ 2026'!$P$6:$P$25) | D13: =SUMIF('5. ΕΝΟΠΟΙΗΜΕΝΑ ΔΕΔΟΜΕΝΑ 2026'!$C$6:$C$25, A13, '5. ΕΝΟΠΟΙΗΜΕΝΑ ΔΕΔΟΜΕΝΑ 2026'!$S$6:$S$25) | E13: =C13-D13 | F13: =SUMIF('5. ΕΝΟΠΟΙΗΜΕΝΑ ΔΕΔΟΜΕΝΑ 2026'!$C$6:$C$25, A13, '5. ΕΝΟΠΟΙΗΜΕΝΑ ΔΕΔΟΜΕΝΑ 2026'!$T$6:$T$25) | G13: =IF(D13=0, 0, ROUND(F13/D13, 4)) | H13: =SUMIF('5. ΕΝΟΠΟΙΗΜΕΝΑ ΔΕΔΟΜΕΝΑ 2026'!$C$6:$C$25, A13, '5. ΕΝΟΠΟΙΗΜΕΝΑ ΔΕΔΟΜΕΝΑ 2026'!$V$6:$V$25) | I13: =IF(F13=0, 0, ROUND(H13/F13, 4)) | J13: =SUMIF('5. ΕΝΟΠΟΙΗΜΕΝΑ ΔΕΔΟΜΕΝΑ 2026'!$C$6:$C$25, A13, '5. ΕΝΟΠΟΙΗΜΕΝΑ ΔΕΔΟΜΕΝΑ 2026'!$X$6:$X$25)
A14: 06/2026 | B14: =COUNTIF('5. ΕΝΟΠΟΙΗΜΕΝΑ ΔΕΔΟΜΕΝΑ 2026'!$C$6:$C$25, A14) | C14: =SUMIF('5. ΕΝΟΠΟΙΗΜΕΝΑ ΔΕΔΟΜΕΝΑ 2026'!$C$6:$C$25, A14, '5. ΕΝΟΠΟΙΗΜΕΝΑ ΔΕΔΟΜΕΝΑ 2026'!$P$6:$P$25) | D14: =SUMIF('5. ΕΝΟΠΟΙΗΜΕΝΑ ΔΕΔΟΜΕΝΑ 2026'!$C$6:$C$25, A14, '5. ΕΝΟΠΟΙΗΜΕΝΑ ΔΕΔΟΜΕΝΑ 2026'!$S$6:$S$25) | E14: =C14-D14 | F14: =SUMIF('5. ΕΝΟΠΟΙΗΜΕΝΑ ΔΕΔΟΜΕΝΑ 2026'!$C$6:$C$25, A14, '5. ΕΝΟΠΟΙΗΜΕΝΑ ΔΕΔΟΜΕΝΑ 2026'!$T$6:$T$25) | G14: =IF(D14=0, 0, ROUND(F14/D14, 4)) | H14: =SUMIF('5. ΕΝΟΠΟΙΗΜΕΝΑ ΔΕΔΟΜΕΝΑ 2026'!$C$6:$C$25, A14, '5. ΕΝΟΠΟΙΗΜΕΝΑ ΔΕΔΟΜΕΝΑ 2026'!$V$6:$V$25) | I14: =IF(F14=0, 0, ROUND(H14/F14, 4)) | J14: =SUMIF('5. ΕΝΟΠΟΙΗΜΕΝΑ ΔΕΔΟΜΕΝΑ 2026'!$C$6:$C$25, A14, '5. ΕΝΟΠΟΙΗΜΕΝΑ ΔΕΔΟΜΕΝΑ 2026'!$X$6:$X$25)
A15: 07/2026 | B15: =COUNTIF('5. ΕΝΟΠΟΙΗΜΕΝΑ ΔΕΔΟΜΕΝΑ 2026'!$C$6:$C$25, A15) | C15: =SUMIF('5. ΕΝΟΠΟΙΗΜΕΝΑ ΔΕΔΟΜΕΝΑ 2026'!$C$6:$C$25, A15, '5. ΕΝΟΠΟΙΗΜΕΝΑ ΔΕΔΟΜΕΝΑ 2026'!$P$6:$P$25) | D15: =SUMIF('5. ΕΝΟΠΟΙΗΜΕΝΑ ΔΕΔΟΜΕΝΑ 2026'!$C$6:$C$25, A15, '5. ΕΝΟΠΟΙΗΜΕΝΑ ΔΕΔΟΜΕΝΑ 2026'!$S$6:$S$25) | E15: =C15-D15 | F15: =SUMIF('5. ΕΝΟΠΟΙΗΜΕΝΑ ΔΕΔΟΜΕΝΑ 2026'!$C$6:$C$25, A15, '5. ΕΝΟΠΟΙΗΜΕΝΑ ΔΕΔΟΜΕΝΑ 2026'!$T$6:$T$25) | G15: =IF(D15=0, 0, ROUND(F15/D15, 4)) | H15: =SUMIF('5. ΕΝΟΠΟΙΗΜΕΝΑ ΔΕΔΟΜΕΝΑ 2026'!$C$6:$C$25, A15, '5. ΕΝΟΠΟΙΗΜΕΝΑ ΔΕΔΟΜΕΝΑ 2026'!$V$6:$V$25) | I15: =IF(F15=0, 0, ROUND(H15/F15, 4)) | J15: =SUMIF('5. ΕΝΟΠΟΙΗΜΕΝΑ ΔΕΔΟΜΕΝΑ 2026'!$C$6:$C$25, A15, '5. ΕΝΟΠΟΙΗΜΕΝΑ ΔΕΔΟΜΕΝΑ 2026'!$X$6:$X$25)
A16: ΣΥΝΟΛΑ 2026: | B16: =SUM(B10:B15) | C16: =SUM(C10:C15) | D16: =SUM(D10:D15) | E16: =SUM(E10:E15) | F16: =SUM(F10:F15) | G16: =ROUND(F16/D16, 4) | H16: =SUM(H10:H15) | I16: =ROUND(H16/F16, 4) | J16: =SUM(J10:J15)
A18: Β. ΚΑΤΑΝΟΜΗ ΠΑΡΑΓΩΓΗΣ ΑΝΑ ΤΥΠΟ ΚΙΝΗΣΗΣ (ΝΕΑ ΠΑΡΑΓΩΓΗ vs ΑΝΑΝΕΩΣΕΙΣ)
A19: Τύπος Κίνησης | B19: Πλήθος Κινήσεων | C19: Μικτά Ασφάλιστρα (€) | D19: Καθαρά Ασφάλιστρα (€) | E19: Προμήθειες Παραγωγών (€) | F19: Υπερπρομήθειες Agency 1411 (€) | G19: Συνολικό Έσοδο 1411 (€)
A20: Νέα Παραγωγή | B20: =COUNTIF('5. ΕΝΟΠΟΙΗΜΕΝΑ ΔΕΔΟΜΕΝΑ 2026'!$Y$6:$Y$25, "*Νέα Παραγωγή*") | C20: =SUMIF('5. ΕΝΟΠΟΙΗΜΕΝΑ ΔΕΔΟΜΕΝΑ 2026'!$Y$6:$Y$25, "*Νέα Παραγωγή*", '5. ΕΝΟΠΟΙΗΜΕΝΑ ΔΕΔΟΜΕΝΑ 2026'!$P$6:$P$25) | D20: =SUMIF('5. ΕΝΟΠΟΙΗΜΕΝΑ ΔΕΔΟΜΕΝΑ 2026'!$Y$6:$Y$25, "*Νέα Παραγωγή*", '5. ΕΝΟΠΟΙΗΜΕΝΑ ΔΕΔΟΜΕΝΑ 2026'!$S$6:$S$25) | E20: =SUMIF('5. ΕΝΟΠΟΙΗΜΕΝΑ ΔΕΔΟΜΕΝΑ 2026'!$Y$6:$Y$25, "*Νέα Παραγωγή*", '5. ΕΝΟΠΟΙΗΜΕΝΑ ΔΕΔΟΜΕΝΑ 2026'!$T$6:$T$25) | F20: =SUMIF('5. ΕΝΟΠΟΙΗΜΕΝΑ ΔΕΔΟΜΕΝΑ 2026'!$Y$6:$Y$25, "*Νέα Παραγωγή*", '5. ΕΝΟΠΟΙΗΜΕΝΑ ΔΕΔΟΜΕΝΑ 2026'!$V$6:$V$25) | G20: =SUMIF('5. ΕΝΟΠΟΙΗΜΕΝΑ ΔΕΔΟΜΕΝΑ 2026'!$Y$6:$Y$25, "*Νέα Παραγωγή*", '5. ΕΝΟΠΟΙΗΜΕΝΑ ΔΕΔΟΜΕΝΑ 2026'!$X$6:$X$25)
A21: Ανανέωση | B21: =COUNTIF('5. ΕΝΟΠΟΙΗΜΕΝΑ ΔΕΔΟΜΕΝΑ 2026'!$Y$6:$Y$25, "*Ανανέωση*") | C21: =SUMIF('5. ΕΝΟΠΟΙΗΜΕΝΑ ΔΕΔΟΜΕΝΑ 2026'!$Y$6:$Y$25, "*Ανανέωση*", '5. ΕΝΟΠΟΙΗΜΕΝΑ ΔΕΔΟΜΕΝΑ 2026'!$P$6:$P$25) | D21: =SUMIF('5. ΕΝΟΠΟΙΗΜΕΝΑ ΔΕΔΟΜΕΝΑ 2026'!$Y$6:$Y$25, "*Ανανέωση*", '5. ΕΝΟΠΟΙΗΜΕΝΑ ΔΕΔΟΜΕΝΑ 2026'!$S$6:$S$25) | E21: =SUMIF('5. ΕΝΟΠΟΙΗΜΕΝΑ ΔΕΔΟΜΕΝΑ 2026'!$Y$6:$Y$25, "*Ανανέωση*", '5. ΕΝΟΠΟΙΗΜΕΝΑ ΔΕΔΟΜΕΝΑ 2026'!$T$6:$T$25) | F21: =SUMIF('5. ΕΝΟΠΟΙΗΜΕΝΑ ΔΕΔΟΜΕΝΑ 2026'!$Y$6:$Y$25, "*Ανανέωση*", '5. ΕΝΟΠΟΙΗΜΕΝΑ ΔΕΔΟΜΕΝΑ 2026'!$V$6:$V$25) | G21: =SUMIF('5. ΕΝΟΠΟΙΗΜΕΝΑ ΔΕΔΟΜΕΝΑ 2026'!$Y$6:$Y$25, "*Ανανέωση*", '5. ΕΝΟΠΟΙΗΜΕΝΑ ΔΕΔΟΜΕΝΑ 2026'!$X$6:$X$25)
A22: Συμψηφισμός 0,00 € | B22: =COUNTIF('5. ΕΝΟΠΟΙΗΜΕΝΑ ΔΕΔΟΜΕΝΑ 2026'!$Y$6:$Y$25, "*Συμψηφισμός*") | C22: =SUMIF('5. ΕΝΟΠΟΙΗΜΕΝΑ ΔΕΔΟΜΕΝΑ 2026'!$Y$6:$Y$25, "*Συμψηφισμός*", '5. ΕΝΟΠΟΙΗΜΕΝΑ ΔΕΔΟΜΕΝΑ 2026'!$P$6:$P$25) | D22: =SUMIF('5. ΕΝΟΠΟΙΗΜΕΝΑ ΔΕΔΟΜΕΝΑ 2026'!$Y$6:$Y$25, "*Συμψηφισμός*", '5. ΕΝΟΠΟΙΗΜΕΝΑ ΔΕΔΟΜΕΝΑ 2026'!$S$6:$S$25) | E22: =SUMIF('5. ΕΝΟΠΟΙΗΜΕΝΑ ΔΕΔΟΜΕΝΑ 2026'!$Y$6:$Y$25, "*Συμψηφισμός*", '5. ΕΝΟΠΟΙΗΜΕΝΑ ΔΕΔΟΜΕΝΑ 2026'!$T$6:$T$25) | F22: =SUMIF('5. ΕΝΟΠΟΙΗΜΕΝΑ ΔΕΔΟΜΕΝΑ 2026'!$Y$6:$Y$25, "*Συμψηφισμός*", '5. ΕΝΟΠΟΙΗΜΕΝΑ ΔΕΔΟΜΕΝΑ 2026'!$V$6:$V$25) | G22: =SUMIF('5. ΕΝΟΠΟΙΗΜΕΝΑ ΔΕΔΟΜΕΝΑ 2026'!$Y$6:$Y$25, "*Συμψηφισμός*", '5. ΕΝΟΠΟΙΗΜΕΝΑ ΔΕΔΟΜΕΝΑ 2026'!$X$6:$X$25)
A23: ΣΥΝΟΛΟ: | B23: =SUM(B20:B22) | C23: =SUM(C20:C22) | D23: =SUM(D20:D22) | E23: =SUM(E20:E22) | F23: =SUM(F20:F22) | G23: =SUM(G20:G22)

Sheet 7. ΣΥΜΒΟΛΑΙΑ & ΚΑΛΥΨΕΙΣ
A1: ΑΝΑΛΥΤΙΚΟ ΜΗΤΡΩΟ ΣΥΜΒΟΛΑΙΩΝ, ΣΤΟΙΧΕΙΩΝ ΠΕΛΑΤΩΝ & ΕΠΙΜΕΡΟΥΣ ΚΑΛΥΨΕΩΝ
A2: Ενότητα Α: Αναλυτική Καταγραφή Όλων των 20 Κινήσεων με Στοιχεία Πελατών & Συμψηφισμούς | Ενότητα Β: Πλήρης Ανάλυση και των 27 Επιμέρους Καλύψεων UATOP615
A4: Α. ΠΛΗΡΗΣ ΚΑΤΑΓΡΑΦΗ ΣΥΜΒΟΛΑΙΩΝ & ΟΙΚΟΝΟΜΙΚΩΝ ΚΙΝΗΣΕΩΝ 2026 (ΜΕ ΟΛΑ ΤΑ ΣΤΟΙΧΕΙΑ ΠΕΛΑΤΗ & ΣΥΜΨΗΦΙΣΜΟΥΣ)
A5: Α/Α | B5: Ημερομηνία Έναρξης | C5: Μήνας | D5: Αρ. Συμβολαίου | E5: Αρ. Απόδειξης | F5: Ονοματεπώνυμο Πελάτη / Επωνυμία | G5: Πακέτο / Πρόγραμμα Ασφάλισης | H5: ΑΦΜ Πελάτη | I5: Τηλέφωνο Επικοινωνίας | J5: Email Πελάτη | K5: Διεύθυνση & Πόλη | L5: Τρόπος Πληρωμής | M5: Διαν. Έτος | N5: Διάρκεια | O5: Μικτά Ασφάλιστρα (€) | P5: Καθαρά ΒΚ - Ζωή (€) | Q5: Καθαρά ΣΚ - Υγεία (€) | R5: Συνολικά Καθαρά (€) | S5: Προμήθεια Συνεργάτη (€) | T5: Προμήθεια % | U5: Υπερπρομήθεια Agency 1411 (€) | V5: Υπερπρομήθεια % | W5: Συνολικό Έσοδο 1411 (€) | X5: Κατάσταση Κίνησης / Συμψηφισμός
A6: 1 | B6: 27/1/2026 | C6: 03/2026 | D6: 2026000161 | E6: 126288 | F6: ΤΕΖΚΟΣΑΡ ΑΓΛΑΙΑ | G6: ERGO Health Care Simple (€500) + Affidea | H6: 141624244 | I6: 6970030570 | J6: hrisafaki@gmail.com | K6: Αφροδίτης 47-49, Παλαιό Φάληρο ΤΚ 17561 | L6: Τριμηνιαία | M6: 1 | N6: 1 | O6: 475.5 | P6: 0 | Q6: 414.55 | R6: 414.55 | S6: 116.18 | T6: 0.2802557 | U6: 23.24 | V6: 0.20003443 | W6: 23.24 | X6: Νέα Παραγωγή (1ο Έτος)
A7: 2 | B7: 29/1/2026 | C7: 02/2026 | D7: 2026000182 | E7: 126309 | F7: ΠΑΠΑΔΑΚΗΣ ΦΑΙΔΩΝ | G7: Ασφάλιση Ζωής & Υγείας | H7: - | I7: - | J7: - | K7: - | L7: Ετήσια | M7: 1 | N7: 1 | O7: 896.3 | P7: 0 | Q7: 896.3 | R7: 896.3 | S7: 0 | T7: 0 | U7: 51.99 | V7: 0.2 | W7: 51.99 | X7: Νέα Παραγωγή (1ο Έτος)
A8: 3 | B8: 2/2/2026 | C8: 04/2026 | D8: 2026000210 | E8: 126337 | F8: ΜΟΥΛΑΚΑΚΗΣ ΓΡΗΓΟΡΙΟΣ (FTTB IKE) | G8: Ασφάλιση Ζωής & Ατυχήματος (Standard Life) | H8: 800769452 | I8: 6948487836 | J8: GMULAKAKIS@GMAIL.COM | K8: Πολυτεχνείου 3, Γάζι ΤΚ 71414 | L8: Ετήσια | M8: 1 | N8: 20 | O8: -1029.77 | P8: -390.36 | Q8: -639.41 | R8: -1029.77 | S8: 0 | T8: 0 | U8: -28.52 | V8: 0.2 | W8: -28.52 | X8: Συμψηφισμός 0,00 € (Αντιλογισμός/Επανέκδοση)
A9: 4 | B9: 2/2/2026 | C9: 04/2026 | D9: 2026000210 | E9: 126337 | F9: ΜΟΥΛΑΚΑΚΗΣ ΓΡΗΓΟΡΙΟΣ (FTTB IKE) | G9: Ασφάλιση Ζωής & Ατυχήματος (Standard Life) | H9: 800769452 | I9: 6948487836 | J9: GMULAKAKIS@GMAIL.COM | K9: Πολυτεχνείου 3, Γάζι ΤΚ 71414 | L9: Ετήσια | M9: 1 | N9: 20 | O9: 1029.77 | P9: 390.36 | Q9: 639.41 | R9: 1029.77 | S9: 0 | T9: 0 | U9: 28.52 | V9: 0.2 | W9: 28.52 | X9: Συμψηφισμός 0,00 € (Αντιλογισμός/Επανέκδοση)
A10: 5 | B10: 14/2/2026 | C10: 03/2026 | D10: 2025000256 | E10: 80404824 | F10: ΒΑΒΑΤΣΙΚΟΣ ΔΗΜΗΤΡΙΟΣ | G10: ERGO Health Care Advanced (€500) | H10: 160251127 | I10: 6985987796 | J10: DIMVAVATSIKOS@GMAIL.COM | K10: Καρπάθου 11, Πειραιάς ΤΚ 18539 | L10: Ετήσια | M10: 2 | N10: 1 | O10: 1309.8 | P10: 0 | Q10: 1093.95 | R10: 1093.95 | S10: 265.07 | T10: 0.24230541 | U10: 53.01 | V10: 0.19998491 | W10: 53.01 | X10: Συμψηφισμός 0,00 € (Αρχική Εγγραφή)
A11: 6 | B11: 14/2/2026 | C11: 03/2026 | D11: 2025000256 | E11: 80404824 | F11: ΒΑΒΑΤΣΙΚΟΣ ΔΗΜΗΤΡΙΟΣ | G11: ERGO Health Care Advanced (€500) | H11: 160251127 | I11: 6985987796 | J11: DIMVAVATSIKOS@GMAIL.COM | K11: Καρπάθου 11, Πειραιάς ΤΚ 18539 | L11: Ετήσια | M11: 2 | N11: 1 | O11: -1309.8 | P11: 0 | Q11: -1093.95 | R11: -1093.95 | S11: -265.07 | T11: 0.24230541 | U11: -53.01 | V11: 0.19998491 | W11: -53.01 | X11: Συμψηφισμός 0,00 € (Ακύρωση/Επανεγγραφή)
A12: 7 | B12: 17/2/2026 | C12: 02/2026 | D12: 2021000340 | E12: 80405097 | F12: ΚΟΥΠΑΛΟΓΛΟΥ ΑΒΑΠΤΙΣΤΟ | G12: ERGO Health Care Advanced | H12: - | I12: - | J12: - | K12: - | L12: Ετήσια | M12: 6 | N12: 1 | O12: 359.74 | P12: 0 | Q12: 359.74 | R12: 359.74 | S12: 89.94 | T12: 0.2500139 | U12: 0 | V12: 0 | W12: 0 | X12: Ανανέωση (6ο Έτος)
A13: 8 | B13: 24/2/2026 | C13: 03/2026 | D13: 2026000457 | E13: 126592 | F13: ΜΟΥΛΑΚΑΚΗΣ ΓΡΗΓΟΡΙΟΣ (FTTB IKE) | G13: Ασφάλιση Ζωής & Ατυχήματος (Standard Life) | H13: 800769452 | I13: 6948487836 | J13: GMULAKAKIS@GMAIL.COM | K13: Πολυτεχνείου 3, Γάζι ΤΚ 71414 | L13: Ετήσια | M13: 1 | N13: 20 | O13: 966.6 | P13: 390.36 | Q13: 483.8 | R13: 874.16 | S13: 238.11 | T13: 0.27238721 | U13: 47.63 | V13: 0.2000336 | W13: 47.63 | X13: Νέα Παραγωγή (1ο Έτος)
A14: 9 | B14: 21/3/2026 | C14: 03/2026 | D14: 296632 | E14: 80409917 | F14: ΚΟΝΤΟΣ ΚΩΝΣΤΑΝΤΙΝΟΣ | G14: Κλασικό Πρόγραμμα Ζωής & Νοσοκομειακό | H14: 124778260 | I14: 6977046967 | J14: - | K14: Συν/ρχη Πλέσσα 84, Καλλιθέα ΤΚ 17674 | L14: Τριμηνιαία | M14: 27 | N14: 99 | O14: 252.9 | P14: 16.57 | Q14: 199.54 | R14: 216.11 | S14: 0 | T14: 0 | U14: 0 | V14: 0 | W14: 0 | X14: Ανανέωση (27ο Έτος)
A15: 10 | B15: 27/3/2026 | C15: 03/2026 | D15: 2022005568 | E15: 80410903 | F15: ΣΑΡΑΦΙΔΟΥ ΕΛΕΝΗ | G15: ERGO My Saving Simple | H15: - | I15: - | J15: - | K15: - | L15: Εξαμηνιαία | M15: 4 | N15: 25 | O15: 75 | P15: 63.92 | Q15: 8.97 | R15: 72.89 | S15: 6.18 | T15: 0.084785293 | U15: 0 | V15: 0 | W15: 0 | X15: Ανανέωση (4ο Έτος)
A16: 11 | B16: 27/3/2026 | C16: 03/2026 | D16: 2025001066 | E16: 80410942 | F16: ΚΑΤΣΙΓΙΑΝΝΑΚΗ ΚΑΛΛΙΟΠΗ | G16: ERGO Health Care Simple | H16: - | I16: - | J16: - | K16: - | L16: Τριμηνιαία | M16: 1 | N16: 15 | O16: 160 | P16: 138.63 | Q16: 7 | R16: 145.63 | S16: 0 | T16: 0 | U16: 3.56 | V16: 0.2 | W16: 3.56 | X16: Νέα Παραγωγή (1ο Έτος)
A17: 12 | B17: 30/3/2026 | C17: 03/2026 | D17: 2025001836 | E17: 80411824 | F17: ΣΤΕΡΓΙΟΥ ΑΒΑΠΤΙΣΤΟ | G17: ERGO Health Care Simple | H17: - | I17: - | J17: - | K17: - | L17: Τριμηνιαία | M17: 1 | N17: 1 | O17: 195 | P17: 0 | Q17: 174.8 | R17: 174.8 | S17: 0 | T17: 0 | U17: 9.84 | V17: 0.2 | W17: 9.84 | X17: Νέα Παραγωγή (1ο Έτος)
... A25: 20 | B25: 27/7/2026 | C25: 07/2026 | D25: 2026000161 | E25: 80430703 | F25: ΤΕΖΚΟΣΑΡ ΑΓΛΑΙΑ | G25: ERGO Health Care Simple (€500) + Affidea | H25: 141624244 | I25: 6970030570 | J25: hrisafaki@gmail.com | K25: Αφροδίτης 47-49, Παλαιό Φάληρο ΤΚ 17561 | L25: Τριμηνιαία | M25: 1 | N25: 1 | O25: 475.5 | P25: 0 | Q25: 414.55 | R25: 414.55 | S25: 116.18 | T25: 0.2802557 | U25: 23.24 | V25: 0.20003443 | W25: 23.24 | X25: Νέα Παραγωγή (1ο Έτος)
A26: ΣΥΝΟΛΑ ΚΙΝΗΣΕΩΝ 2026: | O26: =SUM(O6:O25) | P26: =SUM(P6:P25) | Q26: =SUM(Q6:Q25) | R26: =SUM(R6:R25) | S26: =SUM(S6:S25) | T26: =ROUND(S26/R26, 4) | U26: =SUM(U6:U25) | V26: =ROUND(U26/S26, 4) | W26: =SUM(W6:W25)
A29: Β. ΑΝΑΛΥΤΙΚΗ ΚΑΤΑΓΡΑΦΗ ΟΛΩΝ ΤΩΝ ΕΠΙΜΕΡΟΥΣ ΚΑΛΥΨΕΩΝ (UATOP615 COVERAGES LEDGER)
A30: Α/Α | B30: Αρ. Συμβολαίου | C30: Αρ. Απόδειξης | D30: Ονοματεπώνυμο Πελάτη / Επωνυμία | E30: Πακέτο / Πρόγραμμα Ασφάλισης | F30: ΑΦΜ Πελάτη | G30: Τηλέφωνο | H30: Email Πελάτη | I30: Κωδικός Κάλυψης (F615KAL) | J30: Περιγραφή Κάλυψης / Παροχής (F615PER) | K30: Ασφαλισμένο Κεφάλαιο (€) | L30: Ποσό Απαλλαγής (€) | M30: Καθαρό Ασφάλιστρο Κάλυψης (€) | N30: Προμήθεια Παραγωγού (€) | O30: Προμήθεια % | P30: Υπερπρομήθεια Agency 1411 (€) | Q30: Υπερπρομήθεια % | R30: Συνολικό Έσοδο 1411 (€)
A31: 1 | B31: 2026000765 | C31: 126897 | D31: ΠΑΛΙΑΤΣΑΣ ΑΘΑΝΑΣΙΟΣ | E31: ERGO Health Care Superior (€1.500) | F31: 135971330 | G31: 6947904961 | H31: THANASISPALIATSAS@GMAIL.COM | I31: 20318 | J31: ERGO HEALTH CARE SUPERIOR ΑΠΑΛΛΑΓΗ 1.500 | K31: 750000 | L31: 1500 | M31: 666.12 | N31: 193.17 | O31: 0.28999279 | P31: 38.63 | Q31: 0.2 | R31: 231.8
A32: 2 | B32: 2026000765 | C32: 126897 | D32: ΠΑΛΙΑΤΣΑΣ ΑΘΑΝΑΣΙΟΣ | E32: ERGO Health Care Superior (€1.500) | F32: 135971330 | G32: 6947904961 | H32: THANASISPALIATSAS@GMAIL.COM | I32: 112018 | J32: ERGO HEALTH CARE SUPERIOR | K32: 0 | L32: 0 | M32: 0 | N32: 0 | O32: 0 | P32: 0 | Q32: 0 | R32: 0
A33: 3 | B33: 2026000161 | C33: 80430703 | D33: ΤΕΖΚΟΣΑΡ ΑΓΛΑΙΑ | E33: ERGO Health Care Simple (€500) + Affidea | F33: 141624244 | G33: 6970030570 | H33: hrisafaki@gmail.com | I33: 21018 | J33: ERGO HEALTH CARE SIMPLE ΑΠΑΛΛΑΓΗ 500 | K33: 300000 | L33: 500 | M33: 301 | N33: 108.9 | O33: 0.36179402 | P33: 21.78 | Q33: 0.2 | R33: 130.68
A34: 4 | B34: 2026000161 | C34: 80430703 | D34: ΤΕΖΚΟΣΑΡ ΑΓΛΑΙΑ | E34: ERGO Health Care Simple (€500) + Affidea | F34: 141624244 | G34: 6970030570 | H34: hrisafaki@gmail.com | I34: 20121 | J34: Πρωτοβάθμια Περίθαλψη Υγείας 1 | K34: 0 | L34: 0 | M34: 13.23 | N34: 0 | O34: 0 | P34: 0 | Q34: 0 | R34: 0
A35: 5 | B35: 2026000161 | C35: 80430703 | D35: ΤΕΖΚΟΣΑΡ ΑΓΛΑΙΑ | E35: ERGO Health Care Simple (€500) + Affidea | F35: 141624244 | G35: 6970030570 | H35: hrisafaki@gmail.com | I35: 20121 | J35: Πρωτοβάθμια Περίθαλψη Υγείας 1 | K35: 0 | L35: 0 | M35: 14.55 | N35: 7.28 | O35: 0.50034364 | P35: 1.46 | Q35: 0.2 | R35: 8.74
A36: 6 | B36: 2026000161 | C36: 80430703 | D36: ΤΕΖΚΟΣΑΡ ΑΓΛΑΙΑ | E36: ERGO Health Care Simple (€500) + Affidea | F36: 141624244 | G36: 6970030570 | H36: hrisafaki@gmail.com | I36: 112218 | J36: ERGO HEALTH CARE SIMPLE | K36: 0 | L36: 0 | M36: 0 | N36: 0 | O36: 0 | P36: 0 | Q36: 0 | R36: 0
A37: 7 | B37: 2026000161 | C37: 80430703 | D37: ΤΕΖΚΟΣΑΡ ΑΓΛΑΙΑ | E37: ERGO Health Care Simple (€500) + Affidea | F37: 141624244 | G37: 6970030570 | H37: hrisafaki@gmail.com | I37: 21018 | J37: ERGO HEALTH CARE SIMPLE ΑΠΑΛΛΑΓΗ 500 | K37: 300000 | L37: 500 | M37: 85.77 | N37: 0 | O37: 0 | P37: 0 | Q37: 0 | R37: 0
A38: 8 | B38: 2025000256 | C38: 80404824 | D38: ΒΑΒΑΤΣΙΚΟΣ ΔΗΜΗΤΡΙΟΣ | E38: ERGO Health Care Advanced (€500) | F38: 160251127 | G38: 6985987796 | H38: DIMVAVATSIKOS@GMAIL.COM | I38: 20718 | J38: ERGO HEALTH CARE ADVANCED ΑΠΑΛΛΑΓΗ 500 | K38: 300000 | L38: 500 | M38: -813.27 | N38: -203.32 | O38: 0.25000307 | P38: -40.66 | Q38: 0.2 | R38: -243.98
A39: 9 | B39: 2026000457 | C39: 126592 | D39: ΜΟΥΛΑΚΑΚΗΣ ΓΡΗΓΟΡΙΟΣ (FTTB IKE) | E39: Ασφάλιση Ζωής & Ατυχήματος (Standard Life) | F39: 800769452 | G39: 6948487836 | H39: GMULAKAKIS@GMAIL.COM | I39: 110318 | J39: ΠΡΟΣΚΑΙΡΗ ΑΣΦΑΛΙΣΗ ΘΑΝΑΤΟΥ | K39: 30000 | L39: 0 | M39: 390.36 | N39: 97.59 | O39: 0.25 | P39: 19.52 | Q39: 0.2 | R39: 117.11
A40: 10 | B40: 2023001613 | C40: 80412743 | D40: ΤΑΡΑΝΗΣ ΙΓΝΑΤΙΟΣ | E40: ERGO Health Care Advanced (€3.000) | F40: 111087841 | G40: 6978650501 | H40: - | I40: 112118 | J40: ERGO HEALTH CARE ADVANCED | K40: 0 | L40: 0 | M40: 0 | N40: 0 | O40: 0 | P40: 0 | Q40: 0 | R40: 0
A41: 11 | B41: 2026000161 | C41: 80415871 | D41: ΤΕΖΚΟΣΑΡ ΑΓΛΑΙΑ | E41: ERGO Health Care Simple (€500) + Affidea | F41: 141624244 | G41: 6970030570 | H41: hrisafaki@gmail.com | I41: 112218 | J41: ERGO HEALTH CARE SIMPLE | K41: 0 | L41: 0 | M41: 0 | N41: 0 | O41: 0 | P41: 0 | Q41: 0 | R41: 0
A42: 12 | B42: 2023001613 | C42: 80412743 | D42: ΤΑΡΑΝΗΣ ΙΓΝΑΤΙΟΣ | E42: ERGO Health Care Advanced (€3.000) | F42: 111087841 | G42: 6978650501 | H42: - | I42: 20918 | J42: ERGO HEALTH CARE ADVANCED ΑΠΑΛΛΑΓΗ 3.000 | K42: 300000 | L42: 3000 | M42: 202.37 | N42: 50.59 | O42: 0.24998765 | P42: 10.12 | Q42: 0.2 | R42: 60.71
... A57: 27 | B57: 2025001015 | C57: 80425144 | D57: ΚΟΥΚΛΑΡΗ ΖΩΗ ΓΕΩΡΓΙΑ | E57: ERGO Health Care Advanced (€500) | F57: 172315352 | G57: 6988005415 | H57: GIO_26310@HOTMAIL.COM | I57: 20718 | J57: ERGO HEALTH CARE ADVANCED ΑΠΑΛΛΑΓΗ 500 | K57: 300000 | L57: 500 | M57: 671.05 | N57: 167.76 | O57: 0.24999627 | P57: 33.55 | Q57: 0.2 | R57: 201.31
A58: ΣΥΝΟΛΑ ΚΑΛΥΨΕΩΝ (UATOP615): | K58: =SUM(K31:K57) | L58: =SUM(L31:L57) | M58: =SUM(M31:M57) | N58: =SUM(N31:N57) | O58: =ROUND(N58/M58, 4) | P58: =SUM(P31:P57) | Q58: =ROUND(P58/N58, 4) | R58: =SUM(R31:R57)

Sheet 8. ΥΠΕΡΠΡΟΜΗΘΕΙΕΣ AGENCY
A1: ΕΚΚΑΘΑΡΙΣΗ ΥΠΕΡΠΡΟΜΗΘΕΙΩΝ AGENCY (ΓΡΑΦΕΙΟ 1411 - LANCA Ε.Ε.)
A2: Αναλυτική Λίστα Όλων των Εγγραφών με Βαθμίδα AGENCY (Υπερπρομήθειες Δικτύου Γραφείου) ανά Ημερομηνία Έναρξης / Έκδοσης με Πακέτο & Στοιχεία Πελάτη
A3: ► ΕΠΙΣΗΜΗ ΚΑΤΗΓΟΡΙΑ AGENCY: ΚΛΙΜΑΚΑ Γ (Ανώτατη Βαθμίδα Συντονιστή Β' / Agency ERGO - Υπερπρομήθεια Δικτύου 20,00% επί των Προμηθειών)
A5: Α/Α | B5: Ημερομηνία Έναρξης | C5: Μήνας Εκκαθάρισης | D5: Αρ. Συμβολαίου | E5: Αρ. Απόδειξης | F5: Βαθμίδα / Ρόλος | G5: Κατηγορία / Κλίμακα ERGO | H5: Κωδικός Γραφείου | I5: Επωνυμία Γραφείου | J5: Ονοματεπώνυμο Πελάτη / Επωνυμία | K5: Πακέτο / Πρόγραμμα Ασφάλισης | L5: ΑΦΜ Πελάτη | M5: Τηλέφωνο | N5: Διεύθυνση & Πόλη | O5: Τρόπος Πληρωμής | P5: Διαν. Έτος | Q5: Διάρκεια | R5: Μικτά Ασφάλιστρα (€) | S5: Καθαρά ΒΚ - Ζωή (€) | T5: Καθαρά ΣΚ - Υγεία (€) | U5: Συνολικά Καθαρά (€) | V5: Υπερπρομήθεια ΒΚ (€) | W5: Υπερπρομήθεια ΣΚ (€) | X5: Συνολική Υπερπρομήθεια Agency (€) | Y5: Ποσοστό Υπερπρομήθειας % | Z5: Είδος Κίνησης & Σημείωση Συμψηφισμού
A6: 1 | B6: 27/1/2026 | C6: 03/2026 | D6: 2026000161 | E6: 126288 | F6: AGENCY | G6: Κλίμακα Γ (Agency 20%) | H6: 1411 | I6: LANCA Ι.Κ.Ε. | J6: ΤΕΖΚΟΣΑΡ ΑΓΛΑΙΑ | K6: ERGO Health Care Simple (€500) + Affidea | L6: 141624244 | M6: 6970030570 | N6: Αφροδίτης 47-49, Παλαιό Φάληρο ΤΚ 17561 | O6: Τριμηνιαία | P6: 1 | Q6: 1 | R6: 475.5 | S6: 0 | T6: 414.55 | U6: 414.55 | V6: 0 | W6: 23.24 | X6: 23.24 | Y6: 0.056060789 | Z6: Υπερπρομήθεια Νέας Παραγωγής (1ο Έτος)
A7: 2 | B7: 29/1/2026 | C7: 02/2026 | D7: 2026000182 | E7: 126309 | F7: AGENCY | G7: Κλίμακα Γ (Agency 20%) | H7: 1411 | I7: LANCA Ι.Κ.Ε. | J7: ΠΑΠΑΔΑΚΗΣ ΦΑΙΔΩΝ | K7: Ασφάλιση Ζωής & Υγείας | L7: - | M7: - | N7: - | O7: Ετήσια | P7: 1 | Q7: 1 | R7: 896.3 | S7: 0 | T7: 896.3 | U7: 896.3 | V7: 0 | W7: 51.99 | X7: 51.99 | Y7: 0.058005132 | Z7: Υπερπρομήθεια Νέας Παραγωγής (1ο Έτος)
A8: 3 | B8: 2/2/2026 | C8: 04/2026 | D8: 2026000210 | E8: 126337 | F8: AGENCY | G8: Κλίμακα Γ (Agency 20%) | H8: 1411 | I8: LANCA Ι.Κ.Ε. | J8: ΜΟΥΛΑΚΑΚΗΣ ΓΡΗΓΟΡΙΟΣ (FTTB IKE) | K8: Ασφάλιση Ζωής & Ατυχήματος (Standard Life) | L8: 800769452 | M8: 6948487836 | N8: Πολυτεχνείου 3, Γάζι ΤΚ 71414 | O8: Ετήσια | P8: 1 | Q8: 20 | R8: -1029.77 | S8: -390.36 | T8: -639.41 | U8: -1029.77 | V8: -9.76 | W8: -18.76 | X8: -28.52 | Y8: 0.027695505 | Z8: Αντιλογισμός & Επανέκδοση (Συμψηφισμός 0,00 €)
A9: 4 | B9: 2/2/2026 | C9: 04/2026 | D9: 2026000210 | E9: 126337 | F9: AGENCY | G9: Κλίμακα Γ (Agency 20%) | H9: 1411 | I9: LANCA Ι.Κ.Ε. | J9: ΜΟΥΛΑΚΑΚΗΣ ΓΡΗΓΟΡΙΟΣ (FTTB IKE) | K9: Ασφάλιση Ζωής & Ατυχήματος (Standard Life) | L9: 800769452 | M9: 6948487836 | N9: Πολυτεχνείου 3, Γάζι ΤΚ 71414 | O9: Ετήσια | P9: 1 | Q9: 20 | R9: 1029.77 | S9: 390.36 | T9: 639.41 | U9: 1029.77 | V9: 9.76 | W9: 18.76 | X9: 28.52 | Y9: 0.027695505 | Z9: Αντιλογισμός & Επανέκδοση (Συμψηφισμός 0,00 €)
A10: 5 | B10: 14/2/2026 | C10: 03/2026 | D10: 2025000256 | E10: 80404824 | F10: AGENCY | G10: Κλίμακα Γ (Agency 20%) | H10: 1411 | I10: LANCA Ι.Κ.Ε. | J10: ΒΑΒΑΤΣΙΚΟΣ ΔΗΜΗΤΡΙΟΣ | K10: ERGO Health Care Advanced (€500) | L10: 160251127 | M10: 6985987796 | N10: Καρπάθου 11, Πειραιάς ΤΚ 18539 | O10: Ετήσια | P10: 2 | Q10: 1 | R10: 1309.8 | S10: 0 | T10: 1093.95 | U10: 1093.95 | V10: 0 | W10: 53.01 | X10: 53.01 | Y10: 0.048457425 | Z10: Αρχική Εγγραφή Συμβολαίου (Συμψηφισμός 0,00 €)
A11: 6 | B11: 14/2/2026 | C11: 03/2026 | D11: 2025000256 | E11: 80404824 | F11: AGENCY | G11: Κλίμακα Γ (Agency 20%) | H11: 1411 | I11: LANCA Ι.Κ.Ε. | J11: ΒΑΒΑΤΣΙΚΟΣ ΔΗΜΗΤΡΙΟΣ | K11: ERGO Health Care Advanced (€500) | L11: 160251127 | M11: 6985987796 | N11: Καρπάθου 11, Πειραιάς ΤΚ 18539 | O11: Ετήσια | P11: 2 | Q11: 1 | R11: -1309.8 | S11: 0 | T11: -1093.95 | U11: -1093.95 | V11: 0 | W11: -53.01 | X11: -53.01 | Y11: 0.048457425 | Z11: Ακύρωση & Επιστροφή (Συμψηφισμός 0,00 €)
A12: 7 | B12: 24/2/2026 | C12: 03/2026 | D12: 2026000457 | E12: 126592 | F12: AGENCY | G12: Κλίμακα Γ (Agency 20%) | H12: 1411 | I12: LANCA Ι.Κ.Ε. | J12: ΜΟΥΛΑΚΑΚΗΣ ΓΡΗΓΟΡΙΟΣ (FTTB IKE) | K12: Ασφάλιση Ζωής & Ατυχήματος (Standard Life) | L12: 800769452 | M12: 6948487836 | N12: Πολυτεχνείου 3, Γάζι ΤΚ 71414 | O12: Ετήσια | P12: 1 | Q12: 20 | R12: 966.6 | S12: 390.36 | T12: 483.8 | U12: 874.16 | V12: 19.52 | W12: 28.11 | X12: 47.63 | Y12: 0.054486593 | Z12: Υπερπρομήθεια Νέας Παραγωγής (1ο Έτος)
A13: 8 | B13: 27/3/2026 | C13: 03/2026 | D13: 2025001066 | E13: 80410942 | F13: AGENCY | G13: Κλίμακα Γ (Agency 20%) | H13: 1411 | I13: LANCA Ι.Κ.Ε. | J13: ΚΑΤΣΙΓΙΑΝΝΑΚΗ ΚΑΛΛΙΟΠΗ | K13: ERGO Health Care Simple | L13: - | M13: - | N13: - | O13: Τριμηνιαία | P13: 1 | Q13: 15 | R13: 160 | S13: 138.63 | T13: 7 | U13: 145.63 | V13: 3.37 | W13: 0.19 | X13: 3.56 | Y13: 0.024445513 | Z13: Υπερπρομήθεια Νέας Παραγωγής (1ο Έτος)
A14: 9 | B14: 30/3/2026 | C14: 03/2026 | D14: 2025001836 | E14: 80411824 | F14: AGENCY | G14: Κλίμακα Γ (Agency 20%) | H14: 1411 | I14: LANCA Ι.Κ.Ε. | J14: ΣΤΕΡΓΙΟΥ ΑΒΑΠΤΙΣΤΟ | K14: ERGO Health Care Simple | L14: - | M14: - | N14: - | O14: Τριμηνιαία | P14: 1 | Q14: 1 | R14: 195 | S14: 0 | T14: 174.8 | U14: 174.8 | V14: 0 | W14: 9.84 | X14: 9.84 | Y14: 0.056292906 | Z14: Υπερπρομήθεια Νέας Παραγωγής (1ο Έτος)
A15: 10 | B15: 5/4/2026 | C15: 05/2026 | D15: 2023001613 | E15: 80412743 | F15: AGENCY | G15: Κλίμακα Γ (Agency 20%) | H15: 1411 | I15: LANCA Ι.Κ.Ε. | J15: ΤΑΡΑΝΗΣ ΙΓΝΑΤΙΟΣ | K15: ERGO Health Care Advanced (€3.000) | L15: 111087841 | M15: 6978650501 | N15: Στρ. Μυριβήλη 40, Μυτιλήνη ΤΚ 81100 | O15: Ετήσια | P15: 4 | Q15: 1 | R15: 247.37 | S15: 0 | T15: 202.37 | U15: 202.37 | V15: 0 | W15: 10.12 | X15: 10.12 | Y15: 0.050007412 | Z15: Υπερπρομήθεια Ανανέωσης (4ο Έτος)
A16: 11 | B16: 8/4/2026 | C16: 04/2026 | D16: 2026000765 | E16: 126897 | F16: AGENCY | G16: Κλίμακα Γ (Agency 20%) | H16: 1411 | I16: LANCA Ι.Κ.Ε. | J16: ΠΑΛΙΑΤΣΑΣ ΑΘΑΝΑΣΙΟΣ | K16: ERGO Health Care Superior (€1.500) | L16: 135971330 | M16: 6947904961 | N16: Αιτωλικού 98, Μεσολόγγι ΤΚ 30200 | O16: Ετήσια | P16: 1 | Q16: 1 | R16: 817.8 | S16: 0 | T16: 666.12 | U16: 666.12 | V16: 0 | W16: 38.63 | X16: 38.63 | Y16: 0.057992554 | Z16: Υπερπρομήθεια Νέας Παραγωγής (1ο Έτος)
A17: 12 | B17: 27/4/2026 | C17: 04/2026 | D17: 2026000161 | E17: 80415871 | F17: AGENCY | G17: Κλίμακα Γ (Agency 20%) | H17: 1411 | I17: LANCA Ι.Κ.Ε. | J17: ΤΕΖΚΟΣΑΡ ΑΓΛΑΙΑ | K17: ERGO Health Care Simple (€500) + Affidea | L17: 141624244 | M17: 6970030570 | N17: Αφροδίτης 47-49, Παλαιό Φάληρο ΤΚ 17561 | O17: Τριμηνιαία | P17: 1 | Q17: 1 | R17: 475.5 | S17: 0 | T17: 414.55 | U17: 414.55 | V17: 0 | W17: 23.24 | X17: 23.24 | Y17: 0.056060789 | Z17: Υπερπρομήθεια Νέας Παραγωγής (1ο Έτος)
... A21: 16 | B21: 27/7/2026 | C21: 07/2026 | D21: 2026000161 | E21: 80430703 | F21: AGENCY | G21: Κλίμακα Γ (Agency 20%) | H21: 1411 | I21: LANCA Ι.Κ.Ε. | J21: ΤΕΖΚΟΣΑΡ ΑΓΛΑΙΑ | K21: ERGO Health Care Simple (€500) + Affidea | L21: 141624244 | M21: 6970030570 | N21: Αφροδίτης 47-49, Παλαιό Φάληρο ΤΚ 17561 | O21: Τριμηνιαία | P21: 1 | Q21: 1 | R21: 475.5 | S21: 0 | T21: 414.55 | U21: 414.55 | V21: 0 | W21: 23.24 | X21: 23.24 | Y21: 0.056060789 | Z21: Υπερπρομήθεια Νέας Παραγωγής (1ο Έτος)
A22: ΣΥΝΟΛΑ ΥΠΕΡΠΡΟΜΗΘΕΙΩΝ AGENCY: | R22: =SUM(R6:R21) | S22: =SUM(S6:S21) | T22: =SUM(T6:T21) | U22: =SUM(U6:U21) | V22: =SUM(V6:V21) | W22: =SUM(W6:W21) | X22: =SUM(X6:X21) | Y22: =ROUND(X22/U22, 4)

Sheet 9. ΠΡΟΜΗΘΕΙΕΣ ΣΥΝΕΡΓΑΤΩΝ
A1: ΕΚΚΑΘΑΡΙΣΗ ΠΡΟΜΗΘΕΙΩΝ ΣΥΝΕΡΓΑΤΩΝ / ΠΡΑΚΤΟΡΩΝ ΔΙΚΤΥΟΥ
A2: Αναλυτική Λίστα Όλων των Εγγραφών με Βαθμίδα ΣΥΝΕΡΓΑΤΗΣ (Αμοιβές Πρακτόρων που Έβγαλαν το Συμβόλαιο) ανά Ημερομηνία Έναρξης / Έκδοσης
A3: ► ΕΠΙΣΗΜΗ ΚΑΤΗΓΟΡΙΑ ΣΥΝΕΡΓΑΤΗ: ΚΑΤΗΓΟΡΙΑ Α (Βασική Κλίμακα Παραγωγού ERGO - 29,00% Υγεία / 25,00% Ζωή 1ο Έτος, 25,00% Ανανεώσεις)
A5: Α/Α | B5: Ημερομηνία Έναρξης | C5: Μήνας Εκκαθάρισης | D5: Αρ. Συμβολαίου | E5: Αρ. Απόδειξης | F5: Βαθμίδα / Ρόλος | G5: Κατηγορία / Κλίμακα ERGO | H5: Κωδικός Συνεργάτη | I5: Επωνυμία Συνεργάτη | J5: Ονοματεπώνυμο Πελάτη / Επωνυμία | K5: Πακέτο / Πρόγραμμα Ασφάλισης | L5: ΑΦΜ Πελάτη | M5: Τηλέφωνο | N5: Διεύθυνση & Πόλη | O5: Τρόπος Πληρωμής | P5: Διαν. Έτος | Q5: Διάρκεια | R5: Μικτά Ασφάλιστρα (€) | S5: Καθαρά ΒΚ - Ζωή (€) | T5: Καθαρά ΣΚ - Υγεία (€) | U5: Συνολικά Καθαρά (€) | V5: Προμήθεια ΒΚ (€) | W5: Προμήθεια ΣΚ (€) | X5: Συνολική Προμήθεια Συνεργάτη (€) | Y5: Ποσοστό Προμήθειας % | Z5: Είδος Κίνησης & Σημείωση Συμψηφισμού
